2022-01-05 15:53:17,468 django.utils.autoreload INFO     Watching for file changes with StatReloader
2022-01-05 15:53:19,927 django.request WARNING  Not Found: /
2022-01-05 15:53:23,384 django.request WARNING  Not Found: /aasjasnjas
2022-01-05 15:53:53,579 django.request WARNING  Not Found: /
2022-01-06 14:12:44,812 django.utils.autoreload INFO     Watching for file changes with StatReloader
2022-01-06 14:15:15,462 django.utils.autoreload INFO     Watching for file changes with StatReloader
2022-01-06 14:15:22,871 django.utils.autoreload INFO     C:\Users\nazim\Desktop\estate-src\apps\users\models.py changed, reloading.
2022-01-06 14:15:23,690 django.utils.autoreload INFO     Watching for file changes with StatReloader
2022-01-06 14:39:20,914 django.utils.autoreload INFO     Watching for file changes with StatReloader
2022-01-06 14:39:25,721 django.request WARNING  Not Found: /
2022-01-06 14:39:25,877 django.request WARNING  Not Found: /favicon.ico
2022-01-06 14:40:27,247 django.request ERROR    Internal Server Error: /supersecret/users/user/1/change/
Traceback (most recent call last):
  File "C:\Users\nazim\Desktop\estate-src\env\lib\site-packages\django\contrib\admin\options.py", line 716, in get_form
    return modelform_factory(self.model, **defaults)
  File "C:\Users\nazim\Desktop\estate-src\env\lib\site-packages\django\forms\models.py", line 561, in modelform_factory
    return type(form)(class_name, (form,), form_class_attrs)
  File "C:\Users\nazim\Desktop\estate-src\env\lib\site-packages\django\forms\models.py", line 274, in __new__
    raise FieldError(message)
django.core.exceptions.FieldError: Unknown field(s) (date_joined) specified for User

During handling of the above exception, another exception occurred:

Traceback (most recent call last):
  File "C:\Users\nazim\Desktop\estate-src\env\lib\site-packages\django\core\handlers\exception.py", line 47, in inner
    response = get_response(request)
  File "C:\Users\nazim\Desktop\estate-src\env\lib\site-packages\django\core\handlers\base.py", line 181, in _get_response
    response = wrapped_callback(request, *callback_args, **callback_kwargs)
  File "C:\Users\nazim\Desktop\estate-src\env\lib\site-packages\django\contrib\admin\options.py", line 622, in wrapper
    return self.admin_site.admin_view(view)(*args, **kwargs)
  File "C:\Users\nazim\Desktop\estate-src\env\lib\site-packages\django\utils\decorators.py", line 130, in _wrapped_view
    response = view_func(request, *args, **kwargs)
  File "C:\Users\nazim\Desktop\estate-src\env\lib\site-packages\django\views\decorators\cache.py", line 57, in _wrapped_view_func
    response = view_func(request, *args, **kwargs)
  File "C:\Users\nazim\Desktop\estate-src\env\lib\site-packages\django\contrib\admin\sites.py", line 236, in inner
    return view(request, *args, **kwargs)
  File "C:\Users\nazim\Desktop\estate-src\env\lib\site-packages\django\contrib\admin\options.py", line 1673, in change_view
    return self.changeform_view(request, object_id, form_url, extra_context)
  File "C:\Users\nazim\Desktop\estate-src\env\lib\site-packages\django\utils\decorators.py", line 43, in _wrapper
    return bound_method(*args, **kwargs)
  File "C:\Users\nazim\Desktop\estate-src\env\lib\site-packages\django\utils\decorators.py", line 130, in _wrapped_view
    response = view_func(request, *args, **kwargs)
  File "C:\Users\nazim\Desktop\estate-src\env\lib\site-packages\django\contrib\admin\options.py", line 1549, in changeform_view
    return self._changeform_view(request, object_id, form_url, extra_context)
  File "C:\Users\nazim\Desktop\estate-src\env\lib\site-packages\django\contrib\admin\options.py", line 1583, in _changeform_view
    ModelForm = self.get_form(
  File "C:\Users\nazim\Desktop\estate-src\env\lib\site-packages\django\contrib\auth\admin.py", line 80, in get_form
    return super().get_form(request, obj, **defaults)
  File "C:\Users\nazim\Desktop\estate-src\env\lib\site-packages\django\contrib\admin\options.py", line 718, in get_form
    raise FieldError(
django.core.exceptions.FieldError: Unknown field(s) (date_joined) specified for User. Check fields/fieldsets/exclude attributes of class UserAdmin.
2022-01-06 14:40:32,273 django.request ERROR    Internal Server Error: /supersecret/users/user/1/change/
Traceback (most recent call last):
  File "C:\Users\nazim\Desktop\estate-src\env\lib\site-packages\django\contrib\admin\options.py", line 716, in get_form
    return modelform_factory(self.model, **defaults)
  File "C:\Users\nazim\Desktop\estate-src\env\lib\site-packages\django\forms\models.py", line 561, in modelform_factory
    return type(form)(class_name, (form,), form_class_attrs)
  File "C:\Users\nazim\Desktop\estate-src\env\lib\site-packages\django\forms\models.py", line 274, in __new__
    raise FieldError(message)
django.core.exceptions.FieldError: Unknown field(s) (date_joined) specified for User

During handling of the above exception, another exception occurred:

Traceback (most recent call last):
  File "C:\Users\nazim\Desktop\estate-src\env\lib\site-packages\django\core\handlers\exception.py", line 47, in inner
    response = get_response(request)
  File "C:\Users\nazim\Desktop\estate-src\env\lib\site-packages\django\core\handlers\base.py", line 181, in _get_response
    response = wrapped_callback(request, *callback_args, **callback_kwargs)
  File "C:\Users\nazim\Desktop\estate-src\env\lib\site-packages\django\contrib\admin\options.py", line 622, in wrapper
    return self.admin_site.admin_view(view)(*args, **kwargs)
  File "C:\Users\nazim\Desktop\estate-src\env\lib\site-packages\django\utils\decorators.py", line 130, in _wrapped_view
    response = view_func(request, *args, **kwargs)
  File "C:\Users\nazim\Desktop\estate-src\env\lib\site-packages\django\views\decorators\cache.py", line 57, in _wrapped_view_func
    response = view_func(request, *args, **kwargs)
  File "C:\Users\nazim\Desktop\estate-src\env\lib\site-packages\django\contrib\admin\sites.py", line 236, in inner
    return view(request, *args, **kwargs)
  File "C:\Users\nazim\Desktop\estate-src\env\lib\site-packages\django\contrib\admin\options.py", line 1673, in change_view
    return self.changeform_view(request, object_id, form_url, extra_context)
  File "C:\Users\nazim\Desktop\estate-src\env\lib\site-packages\django\utils\decorators.py", line 43, in _wrapper
    return bound_method(*args, **kwargs)
  File "C:\Users\nazim\Desktop\estate-src\env\lib\site-packages\django\utils\decorators.py", line 130, in _wrapped_view
    response = view_func(request, *args, **kwargs)
  File "C:\Users\nazim\Desktop\estate-src\env\lib\site-packages\django\contrib\admin\options.py", line 1549, in changeform_view
    return self._changeform_view(request, object_id, form_url, extra_context)
  File "C:\Users\nazim\Desktop\estate-src\env\lib\site-packages\django\contrib\admin\options.py", line 1583, in _changeform_view
    ModelForm = self.get_form(
  File "C:\Users\nazim\Desktop\estate-src\env\lib\site-packages\django\contrib\auth\admin.py", line 80, in get_form
    return super().get_form(request, obj, **defaults)
  File "C:\Users\nazim\Desktop\estate-src\env\lib\site-packages\django\contrib\admin\options.py", line 718, in get_form
    raise FieldError(
django.core.exceptions.FieldError: Unknown field(s) (date_joined) specified for User. Check fields/fieldsets/exclude attributes of class UserAdmin.
2022-01-06 14:41:42,376 django.request ERROR    Internal Server Error: /supersecret/users/user/1/change/
Traceback (most recent call last):
  File "C:\Users\nazim\Desktop\estate-src\env\lib\site-packages\django\contrib\admin\options.py", line 716, in get_form
    return modelform_factory(self.model, **defaults)
  File "C:\Users\nazim\Desktop\estate-src\env\lib\site-packages\django\forms\models.py", line 561, in modelform_factory
    return type(form)(class_name, (form,), form_class_attrs)
  File "C:\Users\nazim\Desktop\estate-src\env\lib\site-packages\django\forms\models.py", line 274, in __new__
    raise FieldError(message)
django.core.exceptions.FieldError: Unknown field(s) (date_joined) specified for User

During handling of the above exception, another exception occurred:

Traceback (most recent call last):
  File "C:\Users\nazim\Desktop\estate-src\env\lib\site-packages\django\core\handlers\exception.py", line 47, in inner
    response = get_response(request)
  File "C:\Users\nazim\Desktop\estate-src\env\lib\site-packages\django\core\handlers\base.py", line 181, in _get_response
    response = wrapped_callback(request, *callback_args, **callback_kwargs)
  File "C:\Users\nazim\Desktop\estate-src\env\lib\site-packages\django\contrib\admin\options.py", line 622, in wrapper
    return self.admin_site.admin_view(view)(*args, **kwargs)
  File "C:\Users\nazim\Desktop\estate-src\env\lib\site-packages\django\utils\decorators.py", line 130, in _wrapped_view
    response = view_func(request, *args, **kwargs)
  File "C:\Users\nazim\Desktop\estate-src\env\lib\site-packages\django\views\decorators\cache.py", line 57, in _wrapped_view_func
    response = view_func(request, *args, **kwargs)
  File "C:\Users\nazim\Desktop\estate-src\env\lib\site-packages\django\contrib\admin\sites.py", line 236, in inner
    return view(request, *args, **kwargs)
  File "C:\Users\nazim\Desktop\estate-src\env\lib\site-packages\django\contrib\admin\options.py", line 1673, in change_view
    return self.changeform_view(request, object_id, form_url, extra_context)
  File "C:\Users\nazim\Desktop\estate-src\env\lib\site-packages\django\utils\decorators.py", line 43, in _wrapper
    return bound_method(*args, **kwargs)
  File "C:\Users\nazim\Desktop\estate-src\env\lib\site-packages\django\utils\decorators.py", line 130, in _wrapped_view
    response = view_func(request, *args, **kwargs)
  File "C:\Users\nazim\Desktop\estate-src\env\lib\site-packages\django\contrib\admin\options.py", line 1549, in changeform_view
    return self._changeform_view(request, object_id, form_url, extra_context)
  File "C:\Users\nazim\Desktop\estate-src\env\lib\site-packages\django\contrib\admin\options.py", line 1583, in _changeform_view
    ModelForm = self.get_form(
  File "C:\Users\nazim\Desktop\estate-src\env\lib\site-packages\django\contrib\auth\admin.py", line 80, in get_form
    return super().get_form(request, obj, **defaults)
  File "C:\Users\nazim\Desktop\estate-src\env\lib\site-packages\django\contrib\admin\options.py", line 718, in get_form
    raise FieldError(
django.core.exceptions.FieldError: Unknown field(s) (date_joined) specified for User. Check fields/fieldsets/exclude attributes of class UserAdmin.
2022-01-06 14:42:02,571 django.request ERROR    Internal Server Error: /supersecret/users/user/1/change/
Traceback (most recent call last):
  File "C:\Users\nazim\Desktop\estate-src\env\lib\site-packages\django\contrib\admin\options.py", line 716, in get_form
    return modelform_factory(self.model, **defaults)
  File "C:\Users\nazim\Desktop\estate-src\env\lib\site-packages\django\forms\models.py", line 561, in modelform_factory
    return type(form)(class_name, (form,), form_class_attrs)
  File "C:\Users\nazim\Desktop\estate-src\env\lib\site-packages\django\forms\models.py", line 274, in __new__
    raise FieldError(message)
django.core.exceptions.FieldError: Unknown field(s) (date_joined) specified for User

During handling of the above exception, another exception occurred:

Traceback (most recent call last):
  File "C:\Users\nazim\Desktop\estate-src\env\lib\site-packages\django\core\handlers\exception.py", line 47, in inner
    response = get_response(request)
  File "C:\Users\nazim\Desktop\estate-src\env\lib\site-packages\django\core\handlers\base.py", line 181, in _get_response
    response = wrapped_callback(request, *callback_args, **callback_kwargs)
  File "C:\Users\nazim\Desktop\estate-src\env\lib\site-packages\django\contrib\admin\options.py", line 622, in wrapper
    return self.admin_site.admin_view(view)(*args, **kwargs)
  File "C:\Users\nazim\Desktop\estate-src\env\lib\site-packages\django\utils\decorators.py", line 130, in _wrapped_view
    response = view_func(request, *args, **kwargs)
  File "C:\Users\nazim\Desktop\estate-src\env\lib\site-packages\django\views\decorators\cache.py", line 57, in _wrapped_view_func
    response = view_func(request, *args, **kwargs)
  File "C:\Users\nazim\Desktop\estate-src\env\lib\site-packages\django\contrib\admin\sites.py", line 236, in inner
    return view(request, *args, **kwargs)
  File "C:\Users\nazim\Desktop\estate-src\env\lib\site-packages\django\contrib\admin\options.py", line 1673, in change_view
    return self.changeform_view(request, object_id, form_url, extra_context)
  File "C:\Users\nazim\Desktop\estate-src\env\lib\site-packages\django\utils\decorators.py", line 43, in _wrapper
    return bound_method(*args, **kwargs)
  File "C:\Users\nazim\Desktop\estate-src\env\lib\site-packages\django\utils\decorators.py", line 130, in _wrapped_view
    response = view_func(request, *args, **kwargs)
  File "C:\Users\nazim\Desktop\estate-src\env\lib\site-packages\django\contrib\admin\options.py", line 1549, in changeform_view
    return self._changeform_view(request, object_id, form_url, extra_context)
  File "C:\Users\nazim\Desktop\estate-src\env\lib\site-packages\django\contrib\admin\options.py", line 1583, in _changeform_view
    ModelForm = self.get_form(
  File "C:\Users\nazim\Desktop\estate-src\env\lib\site-packages\django\contrib\auth\admin.py", line 80, in get_form
    return super().get_form(request, obj, **defaults)
  File "C:\Users\nazim\Desktop\estate-src\env\lib\site-packages\django\contrib\admin\options.py", line 718, in get_form
    raise FieldError(
django.core.exceptions.FieldError: Unknown field(s) (date_joined) specified for User. Check fields/fieldsets/exclude attributes of class UserAdmin.
2022-01-06 14:42:34,086 django.request ERROR    Internal Server Error: /supersecret/users/user/1/change/
Traceback (most recent call last):
  File "C:\Users\nazim\Desktop\estate-src\env\lib\site-packages\django\contrib\admin\options.py", line 716, in get_form
    return modelform_factory(self.model, **defaults)
  File "C:\Users\nazim\Desktop\estate-src\env\lib\site-packages\django\forms\models.py", line 561, in modelform_factory
    return type(form)(class_name, (form,), form_class_attrs)
  File "C:\Users\nazim\Desktop\estate-src\env\lib\site-packages\django\forms\models.py", line 274, in __new__
    raise FieldError(message)
django.core.exceptions.FieldError: Unknown field(s) (date_joined) specified for User

During handling of the above exception, another exception occurred:

Traceback (most recent call last):
  File "C:\Users\nazim\Desktop\estate-src\env\lib\site-packages\django\core\handlers\exception.py", line 47, in inner
    response = get_response(request)
  File "C:\Users\nazim\Desktop\estate-src\env\lib\site-packages\django\core\handlers\base.py", line 181, in _get_response
    response = wrapped_callback(request, *callback_args, **callback_kwargs)
  File "C:\Users\nazim\Desktop\estate-src\env\lib\site-packages\django\contrib\admin\options.py", line 622, in wrapper
    return self.admin_site.admin_view(view)(*args, **kwargs)
  File "C:\Users\nazim\Desktop\estate-src\env\lib\site-packages\django\utils\decorators.py", line 130, in _wrapped_view
    response = view_func(request, *args, **kwargs)
  File "C:\Users\nazim\Desktop\estate-src\env\lib\site-packages\django\views\decorators\cache.py", line 57, in _wrapped_view_func
    response = view_func(request, *args, **kwargs)
  File "C:\Users\nazim\Desktop\estate-src\env\lib\site-packages\django\contrib\admin\sites.py", line 236, in inner
    return view(request, *args, **kwargs)
  File "C:\Users\nazim\Desktop\estate-src\env\lib\site-packages\django\contrib\admin\options.py", line 1673, in change_view
    return self.changeform_view(request, object_id, form_url, extra_context)
  File "C:\Users\nazim\Desktop\estate-src\env\lib\site-packages\django\utils\decorators.py", line 43, in _wrapper
    return bound_method(*args, **kwargs)
  File "C:\Users\nazim\Desktop\estate-src\env\lib\site-packages\django\utils\decorators.py", line 130, in _wrapped_view
    response = view_func(request, *args, **kwargs)
  File "C:\Users\nazim\Desktop\estate-src\env\lib\site-packages\django\contrib\admin\options.py", line 1549, in changeform_view
    return self._changeform_view(request, object_id, form_url, extra_context)
  File "C:\Users\nazim\Desktop\estate-src\env\lib\site-packages\django\contrib\admin\options.py", line 1583, in _changeform_view
    ModelForm = self.get_form(
  File "C:\Users\nazim\Desktop\estate-src\env\lib\site-packages\django\contrib\auth\admin.py", line 80, in get_form
    return super().get_form(request, obj, **defaults)
  File "C:\Users\nazim\Desktop\estate-src\env\lib\site-packages\django\contrib\admin\options.py", line 718, in get_form
    raise FieldError(
django.core.exceptions.FieldError: Unknown field(s) (date_joined) specified for User. Check fields/fieldsets/exclude attributes of class UserAdmin.
2022-01-06 14:43:58,637 django.utils.autoreload INFO     C:\Users\nazim\Desktop\estate-src\apps\users\admin.py changed, reloading.
2022-01-06 14:43:59,504 django.utils.autoreload INFO     Watching for file changes with StatReloader
2022-01-06 14:52:59,302 django.utils.autoreload INFO     Watching for file changes with StatReloader
2022-01-06 16:20:15,554 django.utils.autoreload INFO     Watching for file changes with StatReloader
2022-01-06 16:20:21,535 django.request WARNING  Not Found: /
2022-01-07 13:30:24,396 django.utils.autoreload INFO     Watching for file changes with StatReloader
2022-01-07 13:30:28,364 django.request WARNING  Not Found: /
2022-01-07 13:30:28,673 django.request WARNING  Not Found: /favicon.ico
2022-01-07 13:45:32,794 django.request WARNING  Not Found: /api/v1/users
2022-01-07 13:46:22,304 django.request ERROR    Internal Server Error: /api/v1/auth/users
Traceback (most recent call last):
  File "C:\Users\nazim\Desktop\estate-src\env\lib\site-packages\django\core\handlers\exception.py", line 47, in inner
    response = get_response(request)
  File "C:\Users\nazim\Desktop\estate-src\env\lib\site-packages\django\utils\deprecation.py", line 125, in __call__
    response = self.process_request(request)
  File "C:\Users\nazim\Desktop\estate-src\env\lib\site-packages\django\middleware\common.py", line 54, in process_request
    path = self.get_full_path_with_slash(request)
  File "C:\Users\nazim\Desktop\estate-src\env\lib\site-packages\django\middleware\common.py", line 88, in get_full_path_with_slash
    raise RuntimeError(
RuntimeError: You called this URL via POST, but the URL doesn't end in a slash and you have APPEND_SLASH set. Django can't redirect to the slash URL while maintaining POST data. Change your form to point to 127.0.0.1:8000/api/v1/auth/users/ (note the trailing slash), or set APPEND_SLASH=False in your Django settings.
2022-01-07 13:52:12,802 django.request WARNING  Not Found: /
2022-01-07 13:52:15,515 django.request WARNING  Not Found: /admin
2022-01-07 13:55:51,534 django.request WARNING  Unauthorized: /api/v1/auth/jwt/create/
2022-01-07 17:26:54,049 django.utils.autoreload INFO     Watching for file changes with StatReloader
2022-01-07 17:26:57,887 django.request WARNING  Not Found: /
2022-01-07 17:27:07,910 django.request WARNING  Not Found: /profile
2022-01-07 17:27:21,258 django.request WARNING  Not Found: /api/v1/profile
2022-01-07 17:27:26,851 django.request WARNING  Unauthorized: /api/v1/profile/me/
2022-01-07 17:28:00,946 django.utils.autoreload INFO     C:\Users\nazim\Desktop\estate-src\apps\profiles\views.py changed, reloading.
2022-01-07 17:28:02,158 django.utils.autoreload INFO     Watching for file changes with StatReloader
2022-01-07 17:28:02,498 django.request WARNING  Unauthorized: /api/v1/profile/me/
2022-01-07 17:28:13,564 django.request WARNING  Unauthorized: /api/v1/profile/me/
2022-01-07 17:28:20,867 django.utils.autoreload INFO     C:\Users\nazim\Desktop\estate-src\apps\profiles\views.py changed, reloading.
2022-01-07 17:28:21,962 django.utils.autoreload INFO     Watching for file changes with StatReloader
2022-01-07 17:28:22,642 django.request ERROR    Internal Server Error: /api/v1/profile/me/
Traceback (most recent call last):
  File "C:\Users\nazim\Desktop\estate-src\env\lib\site-packages\django\db\models\fields\__init__.py", line 1822, in get_prep_value
    return int(value)
  File "C:\Users\nazim\Desktop\estate-src\env\lib\site-packages\django\contrib\auth\models.py", line 420, in __int__
    raise TypeError('Cannot cast AnonymousUser to int. Are you trying to use it in place of User?')
TypeError: Cannot cast AnonymousUser to int. Are you trying to use it in place of User?

The above exception was the direct cause of the following exception:

Traceback (most recent call last):
  File "C:\Users\nazim\Desktop\estate-src\env\lib\site-packages\django\core\handlers\exception.py", line 47, in inner
    response = get_response(request)
  File "C:\Users\nazim\Desktop\estate-src\env\lib\site-packages\django\core\handlers\base.py", line 181, in _get_response
    response = wrapped_callback(request, *callback_args, **callback_kwargs)
  File "C:\Users\nazim\Desktop\estate-src\env\lib\site-packages\django\views\decorators\csrf.py", line 54, in wrapped_view
    return view_func(*args, **kwargs)
  File "C:\Users\nazim\Desktop\estate-src\env\lib\site-packages\django\views\generic\base.py", line 69, in view
    return self.dispatch(request, *args, **kwargs)
  File "C:\Users\nazim\Desktop\estate-src\env\lib\site-packages\rest_framework\views.py", line 509, in dispatch
    response = self.handle_exception(exc)
  File "C:\Users\nazim\Desktop\estate-src\env\lib\site-packages\rest_framework\views.py", line 469, in handle_exception
    self.raise_uncaught_exception(exc)
  File "C:\Users\nazim\Desktop\estate-src\env\lib\site-packages\rest_framework\views.py", line 480, in raise_uncaught_exception
    raise exc
  File "C:\Users\nazim\Desktop\estate-src\env\lib\site-packages\rest_framework\views.py", line 506, in dispatch
    response = handler(request, *args, **kwargs)
  File "C:\Users\nazim\Desktop\estate-src\apps\profiles\views.py", line 41, in get
    user_profile = Profile.objects.get(user=user)
  File "C:\Users\nazim\Desktop\estate-src\env\lib\site-packages\django\db\models\manager.py", line 85, in manager_method
    return getattr(self.get_queryset(), name)(*args, **kwargs)
  File "C:\Users\nazim\Desktop\estate-src\env\lib\site-packages\django\db\models\query.py", line 428, in get
    clone = self._chain() if self.query.combinator else self.filter(*args, **kwargs)
  File "C:\Users\nazim\Desktop\estate-src\env\lib\site-packages\django\db\models\query.py", line 974, in filter
    return self._filter_or_exclude(False, args, kwargs)
  File "C:\Users\nazim\Desktop\estate-src\env\lib\site-packages\django\db\models\query.py", line 992, in _filter_or_exclude
    clone._filter_or_exclude_inplace(negate, args, kwargs)
  File "C:\Users\nazim\Desktop\estate-src\env\lib\site-packages\django\db\models\query.py", line 999, in _filter_or_exclude_inplace
    self._query.add_q(Q(*args, **kwargs))
  File "C:\Users\nazim\Desktop\estate-src\env\lib\site-packages\django\db\models\sql\query.py", line 1375, in add_q
    clause, _ = self._add_q(q_object, self.used_aliases)
  File "C:\Users\nazim\Desktop\estate-src\env\lib\site-packages\django\db\models\sql\query.py", line 1396, in _add_q
    child_clause, needed_inner = self.build_filter(
  File "C:\Users\nazim\Desktop\estate-src\env\lib\site-packages\django\db\models\sql\query.py", line 1329, in build_filter
    condition = self.build_lookup(lookups, col, value)
  File "C:\Users\nazim\Desktop\estate-src\env\lib\site-packages\django\db\models\sql\query.py", line 1180, in build_lookup
    lookup = lookup_class(lhs, rhs)
  File "C:\Users\nazim\Desktop\estate-src\env\lib\site-packages\django\db\models\lookups.py", line 22, in __init__
    self.rhs = self.get_prep_lookup()
  File "C:\Users\nazim\Desktop\estate-src\env\lib\site-packages\django\db\models\fields\related_lookups.py", line 120, in get_prep_lookup
    self.rhs = target_field.get_prep_value(self.rhs)
  File "C:\Users\nazim\Desktop\estate-src\env\lib\site-packages\django\db\models\fields\__init__.py", line 1824, in get_prep_value
    raise e.__class__(
TypeError: Field 'pkid' expected a number but got <django.contrib.auth.models.AnonymousUser object at 0x000002E3B7D0B6D0>.
2022-01-07 17:28:24,464 django.request ERROR    Internal Server Error: /api/v1/profile/me/
Traceback (most recent call last):
  File "C:\Users\nazim\Desktop\estate-src\env\lib\site-packages\django\db\models\fields\__init__.py", line 1822, in get_prep_value
    return int(value)
  File "C:\Users\nazim\Desktop\estate-src\env\lib\site-packages\django\contrib\auth\models.py", line 420, in __int__
    raise TypeError('Cannot cast AnonymousUser to int. Are you trying to use it in place of User?')
TypeError: Cannot cast AnonymousUser to int. Are you trying to use it in place of User?

The above exception was the direct cause of the following exception:

Traceback (most recent call last):
  File "C:\Users\nazim\Desktop\estate-src\env\lib\site-packages\django\core\handlers\exception.py", line 47, in inner
    response = get_response(request)
  File "C:\Users\nazim\Desktop\estate-src\env\lib\site-packages\django\core\handlers\base.py", line 181, in _get_response
    response = wrapped_callback(request, *callback_args, **callback_kwargs)
  File "C:\Users\nazim\Desktop\estate-src\env\lib\site-packages\django\views\decorators\csrf.py", line 54, in wrapped_view
    return view_func(*args, **kwargs)
  File "C:\Users\nazim\Desktop\estate-src\env\lib\site-packages\django\views\generic\base.py", line 69, in view
    return self.dispatch(request, *args, **kwargs)
  File "C:\Users\nazim\Desktop\estate-src\env\lib\site-packages\rest_framework\views.py", line 509, in dispatch
    response = self.handle_exception(exc)
  File "C:\Users\nazim\Desktop\estate-src\env\lib\site-packages\rest_framework\views.py", line 469, in handle_exception
    self.raise_uncaught_exception(exc)
  File "C:\Users\nazim\Desktop\estate-src\env\lib\site-packages\rest_framework\views.py", line 480, in raise_uncaught_exception
    raise exc
  File "C:\Users\nazim\Desktop\estate-src\env\lib\site-packages\rest_framework\views.py", line 506, in dispatch
    response = handler(request, *args, **kwargs)
  File "C:\Users\nazim\Desktop\estate-src\apps\profiles\views.py", line 41, in get
    user_profile = Profile.objects.get(user=user)
  File "C:\Users\nazim\Desktop\estate-src\env\lib\site-packages\django\db\models\manager.py", line 85, in manager_method
    return getattr(self.get_queryset(), name)(*args, **kwargs)
  File "C:\Users\nazim\Desktop\estate-src\env\lib\site-packages\django\db\models\query.py", line 428, in get
    clone = self._chain() if self.query.combinator else self.filter(*args, **kwargs)
  File "C:\Users\nazim\Desktop\estate-src\env\lib\site-packages\django\db\models\query.py", line 974, in filter
    return self._filter_or_exclude(False, args, kwargs)
  File "C:\Users\nazim\Desktop\estate-src\env\lib\site-packages\django\db\models\query.py", line 992, in _filter_or_exclude
    clone._filter_or_exclude_inplace(negate, args, kwargs)
  File "C:\Users\nazim\Desktop\estate-src\env\lib\site-packages\django\db\models\query.py", line 999, in _filter_or_exclude_inplace
    self._query.add_q(Q(*args, **kwargs))
  File "C:\Users\nazim\Desktop\estate-src\env\lib\site-packages\django\db\models\sql\query.py", line 1375, in add_q
    clause, _ = self._add_q(q_object, self.used_aliases)
  File "C:\Users\nazim\Desktop\estate-src\env\lib\site-packages\django\db\models\sql\query.py", line 1396, in _add_q
    child_clause, needed_inner = self.build_filter(
  File "C:\Users\nazim\Desktop\estate-src\env\lib\site-packages\django\db\models\sql\query.py", line 1329, in build_filter
    condition = self.build_lookup(lookups, col, value)
  File "C:\Users\nazim\Desktop\estate-src\env\lib\site-packages\django\db\models\sql\query.py", line 1180, in build_lookup
    lookup = lookup_class(lhs, rhs)
  File "C:\Users\nazim\Desktop\estate-src\env\lib\site-packages\django\db\models\lookups.py", line 22, in __init__
    self.rhs = self.get_prep_lookup()
  File "C:\Users\nazim\Desktop\estate-src\env\lib\site-packages\django\db\models\fields\related_lookups.py", line 120, in get_prep_lookup
    self.rhs = target_field.get_prep_value(self.rhs)
  File "C:\Users\nazim\Desktop\estate-src\env\lib\site-packages\django\db\models\fields\__init__.py", line 1824, in get_prep_value
    raise e.__class__(
TypeError: Field 'pkid' expected a number but got <django.contrib.auth.models.AnonymousUser object at 0x000002E3B7D362E0>.
2022-01-07 17:28:57,693 django.utils.autoreload INFO     C:\Users\nazim\Desktop\estate-src\apps\profiles\views.py changed, reloading.
2022-01-07 17:28:58,829 django.utils.autoreload INFO     Watching for file changes with StatReloader
2022-01-07 17:28:59,161 django.request WARNING  Unauthorized: /api/v1/profile/me/
2022-01-07 17:31:00,908 django.utils.autoreload INFO     C:\Users\nazim\Desktop\estate-src\apps\profiles\views.py changed, reloading.
2022-01-07 17:31:01,917 django.utils.autoreload INFO     Watching for file changes with StatReloader
2022-01-07 17:31:04,417 django.request WARNING  Unauthorized: /api/v1/profile/me/
2022-01-07 17:31:50,280 django.request WARNING  Unauthorized: /api/v1/profile/me/
2022-01-07 17:31:58,536 django.request WARNING  Unauthorized: /api/v1/auth/jwt/create/
2022-01-07 17:32:27,605 django.request ERROR    Internal Server Error: /api/v1/profile/me/
Traceback (most recent call last):
  File "C:\Users\nazim\Desktop\estate-src\env\lib\site-packages\django\core\handlers\exception.py", line 47, in inner
    response = get_response(request)
  File "C:\Users\nazim\Desktop\estate-src\env\lib\site-packages\django\core\handlers\base.py", line 181, in _get_response
    response = wrapped_callback(request, *callback_args, **callback_kwargs)
  File "C:\Users\nazim\Desktop\estate-src\env\lib\site-packages\django\views\decorators\csrf.py", line 54, in wrapped_view
    return view_func(*args, **kwargs)
  File "C:\Users\nazim\Desktop\estate-src\env\lib\site-packages\django\views\generic\base.py", line 69, in view
    return self.dispatch(request, *args, **kwargs)
  File "C:\Users\nazim\Desktop\estate-src\env\lib\site-packages\rest_framework\views.py", line 509, in dispatch
    response = self.handle_exception(exc)
  File "C:\Users\nazim\Desktop\estate-src\env\lib\site-packages\rest_framework\views.py", line 469, in handle_exception
    self.raise_uncaught_exception(exc)
  File "C:\Users\nazim\Desktop\estate-src\env\lib\site-packages\rest_framework\views.py", line 480, in raise_uncaught_exception
    raise exc
  File "C:\Users\nazim\Desktop\estate-src\env\lib\site-packages\rest_framework\views.py", line 506, in dispatch
    response = handler(request, *args, **kwargs)
  File "C:\Users\nazim\Desktop\estate-src\apps\profiles\views.py", line 43, in get
    return Response(serializer.data, status=status.HTTP_200_OK)
  File "C:\Users\nazim\Desktop\estate-src\env\lib\site-packages\rest_framework\serializers.py", line 555, in data
    ret = super().data
  File "C:\Users\nazim\Desktop\estate-src\env\lib\site-packages\rest_framework\serializers.py", line 253, in data
    self._data = self.to_representation(self.instance)
  File "C:\Users\nazim\Desktop\estate-src\apps\profiles\serializers.py", line 52, in to_representation
    representation = super().to_representation(instance)
  File "C:\Users\nazim\Desktop\estate-src\env\lib\site-packages\rest_framework\serializers.py", line 507, in to_representation
    for field in fields:
  File "C:\Users\nazim\Desktop\estate-src\env\lib\site-packages\rest_framework\serializers.py", line 368, in _readable_fields
    for field in self.fields.values():
  File "C:\Users\nazim\Desktop\estate-src\env\lib\site-packages\django\utils\functional.py", line 48, in __get__
    res = instance.__dict__[self.name] = self.func(instance)
  File "C:\Users\nazim\Desktop\estate-src\env\lib\site-packages\rest_framework\serializers.py", line 356, in fields
    for key, value in self.get_fields().items():
  File "C:\Users\nazim\Desktop\estate-src\env\lib\site-packages\rest_framework\serializers.py", line 1052, in get_fields
    field_names = self.get_field_names(declared_fields, info)
  File "C:\Users\nazim\Desktop\estate-src\env\lib\site-packages\rest_framework\serializers.py", line 1148, in get_field_names
    assert field_name in fields, (
AssertionError: The field 'full_name' was declared on serializer ProfileSerializer, but has not been included in the 'fields' option.
2022-01-07 17:32:40,218 django.request ERROR    Internal Server Error: /api/v1/profile/me/
Traceback (most recent call last):
  File "C:\Users\nazim\Desktop\estate-src\env\lib\site-packages\django\core\handlers\exception.py", line 47, in inner
    response = get_response(request)
  File "C:\Users\nazim\Desktop\estate-src\env\lib\site-packages\django\core\handlers\base.py", line 181, in _get_response
    response = wrapped_callback(request, *callback_args, **callback_kwargs)
  File "C:\Users\nazim\Desktop\estate-src\env\lib\site-packages\django\views\decorators\csrf.py", line 54, in wrapped_view
    return view_func(*args, **kwargs)
  File "C:\Users\nazim\Desktop\estate-src\env\lib\site-packages\django\views\generic\base.py", line 69, in view
    return self.dispatch(request, *args, **kwargs)
  File "C:\Users\nazim\Desktop\estate-src\env\lib\site-packages\rest_framework\views.py", line 509, in dispatch
    response = self.handle_exception(exc)
  File "C:\Users\nazim\Desktop\estate-src\env\lib\site-packages\rest_framework\views.py", line 469, in handle_exception
    self.raise_uncaught_exception(exc)
  File "C:\Users\nazim\Desktop\estate-src\env\lib\site-packages\rest_framework\views.py", line 480, in raise_uncaught_exception
    raise exc
  File "C:\Users\nazim\Desktop\estate-src\env\lib\site-packages\rest_framework\views.py", line 506, in dispatch
    response = handler(request, *args, **kwargs)
  File "C:\Users\nazim\Desktop\estate-src\apps\profiles\views.py", line 43, in get
    return Response(serializer.data, status=status.HTTP_200_OK)
  File "C:\Users\nazim\Desktop\estate-src\env\lib\site-packages\rest_framework\serializers.py", line 555, in data
    ret = super().data
  File "C:\Users\nazim\Desktop\estate-src\env\lib\site-packages\rest_framework\serializers.py", line 253, in data
    self._data = self.to_representation(self.instance)
  File "C:\Users\nazim\Desktop\estate-src\apps\profiles\serializers.py", line 52, in to_representation
    representation = super().to_representation(instance)
  File "C:\Users\nazim\Desktop\estate-src\env\lib\site-packages\rest_framework\serializers.py", line 507, in to_representation
    for field in fields:
  File "C:\Users\nazim\Desktop\estate-src\env\lib\site-packages\rest_framework\serializers.py", line 368, in _readable_fields
    for field in self.fields.values():
  File "C:\Users\nazim\Desktop\estate-src\env\lib\site-packages\django\utils\functional.py", line 48, in __get__
    res = instance.__dict__[self.name] = self.func(instance)
  File "C:\Users\nazim\Desktop\estate-src\env\lib\site-packages\rest_framework\serializers.py", line 356, in fields
    for key, value in self.get_fields().items():
  File "C:\Users\nazim\Desktop\estate-src\env\lib\site-packages\rest_framework\serializers.py", line 1052, in get_fields
    field_names = self.get_field_names(declared_fields, info)
  File "C:\Users\nazim\Desktop\estate-src\env\lib\site-packages\rest_framework\serializers.py", line 1148, in get_field_names
    assert field_name in fields, (
AssertionError: The field 'full_name' was declared on serializer ProfileSerializer, but has not been included in the 'fields' option.
2022-01-07 17:33:26,534 django.utils.autoreload INFO     C:\Users\nazim\Desktop\estate-src\apps\profiles\serializers.py changed, reloading.
2022-01-07 17:33:27,551 django.utils.autoreload INFO     Watching for file changes with StatReloader
2022-01-07 17:33:33,476 django.request ERROR    Internal Server Error: /api/v1/profile/me/
Traceback (most recent call last):
  File "C:\Users\nazim\Desktop\estate-src\env\lib\site-packages\django\core\handlers\exception.py", line 47, in inner
    response = get_response(request)
  File "C:\Users\nazim\Desktop\estate-src\env\lib\site-packages\django\core\handlers\base.py", line 181, in _get_response
    response = wrapped_callback(request, *callback_args, **callback_kwargs)
  File "C:\Users\nazim\Desktop\estate-src\env\lib\site-packages\django\views\decorators\csrf.py", line 54, in wrapped_view
    return view_func(*args, **kwargs)
  File "C:\Users\nazim\Desktop\estate-src\env\lib\site-packages\django\views\generic\base.py", line 69, in view
    return self.dispatch(request, *args, **kwargs)
  File "C:\Users\nazim\Desktop\estate-src\env\lib\site-packages\rest_framework\views.py", line 509, in dispatch
    response = self.handle_exception(exc)
  File "C:\Users\nazim\Desktop\estate-src\env\lib\site-packages\rest_framework\views.py", line 469, in handle_exception
    self.raise_uncaught_exception(exc)
  File "C:\Users\nazim\Desktop\estate-src\env\lib\site-packages\rest_framework\views.py", line 480, in raise_uncaught_exception
    raise exc
  File "C:\Users\nazim\Desktop\estate-src\env\lib\site-packages\rest_framework\views.py", line 506, in dispatch
    response = handler(request, *args, **kwargs)
  File "C:\Users\nazim\Desktop\estate-src\apps\profiles\views.py", line 43, in get
    return Response(serializer.data, status=status.HTTP_200_OK)
  File "C:\Users\nazim\Desktop\estate-src\env\lib\site-packages\rest_framework\serializers.py", line 555, in data
    ret = super().data
  File "C:\Users\nazim\Desktop\estate-src\env\lib\site-packages\rest_framework\serializers.py", line 253, in data
    self._data = self.to_representation(self.instance)
  File "C:\Users\nazim\Desktop\estate-src\apps\profiles\serializers.py", line 53, in to_representation
    representation = super().to_representation(instance)
  File "C:\Users\nazim\Desktop\estate-src\env\lib\site-packages\rest_framework\serializers.py", line 507, in to_representation
    for field in fields:
  File "C:\Users\nazim\Desktop\estate-src\env\lib\site-packages\rest_framework\serializers.py", line 368, in _readable_fields
    for field in self.fields.values():
  File "C:\Users\nazim\Desktop\estate-src\env\lib\site-packages\django\utils\functional.py", line 48, in __get__
    res = instance.__dict__[self.name] = self.func(instance)
  File "C:\Users\nazim\Desktop\estate-src\env\lib\site-packages\rest_framework\serializers.py", line 356, in fields
    for key, value in self.get_fields().items():
  File "C:\Users\nazim\Desktop\estate-src\env\lib\site-packages\rest_framework\serializers.py", line 1076, in get_fields
    field_class, field_kwargs = self.build_field(
  File "C:\Users\nazim\Desktop\estate-src\env\lib\site-packages\rest_framework\serializers.py", line 1222, in build_field
    return self.build_unknown_field(field_name, model_class)
  File "C:\Users\nazim\Desktop\estate-src\env\lib\site-packages\rest_framework\serializers.py", line 1340, in build_unknown_field
    raise ImproperlyConfigured(
django.core.exceptions.ImproperlyConfigured: Field name `ptofile_photo` is not valid for model `Profile`.
2022-01-07 17:33:59,067 django.utils.autoreload INFO     C:\Users\nazim\Desktop\estate-src\apps\profiles\serializers.py changed, reloading.
2022-01-07 17:34:00,221 django.utils.autoreload INFO     Watching for file changes with StatReloader
2022-01-07 21:55:26,862 django.utils.autoreload INFO     Watching for file changes with StatReloader
2022-01-07 21:55:29,652 django.request WARNING  Not Found: /
2022-01-08 17:31:00,274 django.utils.autoreload INFO     Watching for file changes with StatReloader
2022-01-08 17:31:03,503 django.request WARNING  Not Found: /
2022-01-08 17:31:03,750 django.request WARNING  Not Found: /favicon.ico
2022-01-08 17:31:13,882 django.request WARNING  Not Found: /api/v1/properties
2022-01-08 17:31:17,914 django.request WARNING  Not Found: /api/v1/properties/
2022-01-08 17:32:51,573 django.request WARNING  Method Not Allowed: /api/v1/properties/search/
2022-01-08 17:33:30,829 django.request WARNING  Method Not Allowed: /api/v1/properties/search/
2022-01-09 15:40:54,363 django.utils.autoreload INFO     Watching for file changes with StatReloader
2022-01-09 15:40:57,665 django.request WARNING  Not Found: /
2022-01-09 15:40:58,029 django.request WARNING  Not Found: /favicon.ico
2022-01-09 15:41:05,235 django.request WARNING  Method Not Allowed: /api/v1/enquiries/
2022-01-09 15:41:59,731 django.request WARNING  Not Found: /admin
2022-01-09 15:46:37,892 django.request WARNING  Unauthorized: /api/v1/ratings/bf9dd069-f056-4d9a-98f6-d05fa907c8bd/
2022-01-09 15:47:33,622 django.request WARNING  Bad Request: /api/v1/auth/jwt/create/
2022-01-09 15:47:49,306 django.request WARNING  Unauthorized: /api/v1/auth/jwt/create/
2022-01-09 15:48:41,228 django.request ERROR    Internal Server Error: /api/v1/ratings/bf9dd069-f056-4d9a-98f6-d05fa907c8bd/
Traceback (most recent call last):
  File "C:\Users\nazim\Desktop\estate-src\env\lib\site-packages\django\core\handlers\exception.py", line 47, in inner
    response = get_response(request)
  File "C:\Users\nazim\Desktop\estate-src\env\lib\site-packages\django\core\handlers\base.py", line 181, in _get_response
    response = wrapped_callback(request, *callback_args, **callback_kwargs)
  File "C:\Users\nazim\Desktop\estate-src\env\lib\site-packages\django\views\decorators\csrf.py", line 54, in wrapped_view
    return view_func(*args, **kwargs)
  File "C:\Users\nazim\Desktop\estate-src\env\lib\site-packages\django\views\generic\base.py", line 69, in view
    return self.dispatch(request, *args, **kwargs)
  File "C:\Users\nazim\Desktop\estate-src\env\lib\site-packages\rest_framework\views.py", line 509, in dispatch
    response = self.handle_exception(exc)
  File "C:\Users\nazim\Desktop\estate-src\env\lib\site-packages\rest_framework\views.py", line 469, in handle_exception
    self.raise_uncaught_exception(exc)
  File "C:\Users\nazim\Desktop\estate-src\env\lib\site-packages\rest_framework\views.py", line 480, in raise_uncaught_exception
    raise exc
  File "C:\Users\nazim\Desktop\estate-src\env\lib\site-packages\rest_framework\views.py", line 506, in dispatch
    response = handler(request, *args, **kwargs)
  File "C:\Users\nazim\Desktop\estate-src\env\lib\site-packages\rest_framework\decorators.py", line 50, in handler
    return func(*args, **kwargs)
  File "C:\Users\nazim\Desktop\estate-src\apps\ratings\views.py", line 16, in create_agent_review
    agent_profile = Profile.objects.get(id=profile_id, is_agent=True)
  File "C:\Users\nazim\Desktop\estate-src\env\lib\site-packages\django\db\models\manager.py", line 85, in manager_method
    return getattr(self.get_queryset(), name)(*args, **kwargs)
  File "C:\Users\nazim\Desktop\estate-src\env\lib\site-packages\django\db\models\query.py", line 439, in get
    raise self.model.DoesNotExist(
apps.profiles.models.Profile.DoesNotExist: Profile matching query does not exist.
2022-01-09 15:49:19,218 django.request ERROR    Internal Server Error: /api/v1/ratings/bf9dd069-f056-4d9a-98f6-d05fa907c8bd/
Traceback (most recent call last):
  File "C:\Users\nazim\Desktop\estate-src\env\lib\site-packages\django\core\handlers\exception.py", line 47, in inner
    response = get_response(request)
  File "C:\Users\nazim\Desktop\estate-src\env\lib\site-packages\django\core\handlers\base.py", line 181, in _get_response
    response = wrapped_callback(request, *callback_args, **callback_kwargs)
  File "C:\Users\nazim\Desktop\estate-src\env\lib\site-packages\django\views\decorators\csrf.py", line 54, in wrapped_view
    return view_func(*args, **kwargs)
  File "C:\Users\nazim\Desktop\estate-src\env\lib\site-packages\django\views\generic\base.py", line 69, in view
    return self.dispatch(request, *args, **kwargs)
  File "C:\Users\nazim\Desktop\estate-src\env\lib\site-packages\rest_framework\views.py", line 509, in dispatch
    response = self.handle_exception(exc)
  File "C:\Users\nazim\Desktop\estate-src\env\lib\site-packages\rest_framework\views.py", line 469, in handle_exception
    self.raise_uncaught_exception(exc)
  File "C:\Users\nazim\Desktop\estate-src\env\lib\site-packages\rest_framework\views.py", line 480, in raise_uncaught_exception
    raise exc
  File "C:\Users\nazim\Desktop\estate-src\env\lib\site-packages\rest_framework\views.py", line 506, in dispatch
    response = handler(request, *args, **kwargs)
  File "C:\Users\nazim\Desktop\estate-src\env\lib\site-packages\rest_framework\decorators.py", line 50, in handler
    return func(*args, **kwargs)
  File "C:\Users\nazim\Desktop\estate-src\apps\ratings\views.py", line 16, in create_agent_review
    agent_profile = Profile.objects.get(id=profile_id, is_agent=True)
  File "C:\Users\nazim\Desktop\estate-src\env\lib\site-packages\django\db\models\manager.py", line 85, in manager_method
    return getattr(self.get_queryset(), name)(*args, **kwargs)
  File "C:\Users\nazim\Desktop\estate-src\env\lib\site-packages\django\db\models\query.py", line 439, in get
    raise self.model.DoesNotExist(
apps.profiles.models.Profile.DoesNotExist: Profile matching query does not exist.
2022-01-09 15:49:48,916 django.request ERROR    Internal Server Error: /api/v1/ratings/7dfdc7d1-7277-4ae0-aefb-65ce687830a2/
Traceback (most recent call last):
  File "C:\Users\nazim\Desktop\estate-src\env\lib\site-packages\django\core\handlers\exception.py", line 47, in inner
    response = get_response(request)
  File "C:\Users\nazim\Desktop\estate-src\env\lib\site-packages\django\core\handlers\base.py", line 181, in _get_response
    response = wrapped_callback(request, *callback_args, **callback_kwargs)
  File "C:\Users\nazim\Desktop\estate-src\env\lib\site-packages\django\views\decorators\csrf.py", line 54, in wrapped_view
    return view_func(*args, **kwargs)
  File "C:\Users\nazim\Desktop\estate-src\env\lib\site-packages\django\views\generic\base.py", line 69, in view
    return self.dispatch(request, *args, **kwargs)
  File "C:\Users\nazim\Desktop\estate-src\env\lib\site-packages\rest_framework\views.py", line 509, in dispatch
    response = self.handle_exception(exc)
  File "C:\Users\nazim\Desktop\estate-src\env\lib\site-packages\rest_framework\views.py", line 469, in handle_exception
    self.raise_uncaught_exception(exc)
  File "C:\Users\nazim\Desktop\estate-src\env\lib\site-packages\rest_framework\views.py", line 480, in raise_uncaught_exception
    raise exc
  File "C:\Users\nazim\Desktop\estate-src\env\lib\site-packages\rest_framework\views.py", line 506, in dispatch
    response = handler(request, *args, **kwargs)
  File "C:\Users\nazim\Desktop\estate-src\env\lib\site-packages\rest_framework\decorators.py", line 50, in handler
    return func(*args, **kwargs)
  File "C:\Users\nazim\Desktop\estate-src\apps\ratings\views.py", line 16, in create_agent_review
    agent_profile = Profile.objects.get(id=profile_id, is_agent=True)
  File "C:\Users\nazim\Desktop\estate-src\env\lib\site-packages\django\db\models\manager.py", line 85, in manager_method
    return getattr(self.get_queryset(), name)(*args, **kwargs)
  File "C:\Users\nazim\Desktop\estate-src\env\lib\site-packages\django\db\models\query.py", line 439, in get
    raise self.model.DoesNotExist(
apps.profiles.models.Profile.DoesNotExist: Profile matching query does not exist.
2022-01-09 15:51:10,817 django.request ERROR    Internal Server Error: /api/v1/ratings/7dfdc7d1-7277-4ae0-aefb-65ce687830a2/
Traceback (most recent call last):
  File "C:\Users\nazim\Desktop\estate-src\env\lib\site-packages\django\core\handlers\exception.py", line 47, in inner
    response = get_response(request)
  File "C:\Users\nazim\Desktop\estate-src\env\lib\site-packages\django\core\handlers\base.py", line 181, in _get_response
    response = wrapped_callback(request, *callback_args, **callback_kwargs)
  File "C:\Users\nazim\Desktop\estate-src\env\lib\site-packages\django\views\decorators\csrf.py", line 54, in wrapped_view
    return view_func(*args, **kwargs)
  File "C:\Users\nazim\Desktop\estate-src\env\lib\site-packages\django\views\generic\base.py", line 69, in view
    return self.dispatch(request, *args, **kwargs)
  File "C:\Users\nazim\Desktop\estate-src\env\lib\site-packages\rest_framework\views.py", line 509, in dispatch
    response = self.handle_exception(exc)
  File "C:\Users\nazim\Desktop\estate-src\env\lib\site-packages\rest_framework\views.py", line 469, in handle_exception
    self.raise_uncaught_exception(exc)
  File "C:\Users\nazim\Desktop\estate-src\env\lib\site-packages\rest_framework\views.py", line 480, in raise_uncaught_exception
    raise exc
  File "C:\Users\nazim\Desktop\estate-src\env\lib\site-packages\rest_framework\views.py", line 506, in dispatch
    response = handler(request, *args, **kwargs)
  File "C:\Users\nazim\Desktop\estate-src\env\lib\site-packages\rest_framework\decorators.py", line 50, in handler
    return func(*args, **kwargs)
  File "C:\Users\nazim\Desktop\estate-src\apps\ratings\views.py", line 16, in create_agent_review
    agent_profile = Profile.objects.get(id=profile_id, is_agent=True)
  File "C:\Users\nazim\Desktop\estate-src\env\lib\site-packages\django\db\models\manager.py", line 85, in manager_method
    return getattr(self.get_queryset(), name)(*args, **kwargs)
  File "C:\Users\nazim\Desktop\estate-src\env\lib\site-packages\django\db\models\query.py", line 439, in get
    raise self.model.DoesNotExist(
apps.profiles.models.Profile.DoesNotExist: Profile matching query does not exist.
2022-01-09 15:51:19,930 django.request ERROR    Internal Server Error: /api/v1/ratings/7dfdc7d1-7277-4ae0-aefb-65ce687830a2
Traceback (most recent call last):
  File "C:\Users\nazim\Desktop\estate-src\env\lib\site-packages\django\core\handlers\exception.py", line 47, in inner
    response = get_response(request)
  File "C:\Users\nazim\Desktop\estate-src\env\lib\site-packages\django\utils\deprecation.py", line 125, in __call__
    response = self.process_request(request)
  File "C:\Users\nazim\Desktop\estate-src\env\lib\site-packages\django\middleware\common.py", line 54, in process_request
    path = self.get_full_path_with_slash(request)
  File "C:\Users\nazim\Desktop\estate-src\env\lib\site-packages\django\middleware\common.py", line 88, in get_full_path_with_slash
    raise RuntimeError(
RuntimeError: You called this URL via POST, but the URL doesn't end in a slash and you have APPEND_SLASH set. Django can't redirect to the slash URL while maintaining POST data. Change your form to point to 127.0.0.1:8000/api/v1/ratings/7dfdc7d1-7277-4ae0-aefb-65ce687830a2/ (note the trailing slash), or set APPEND_SLASH=False in your Django settings.
2022-01-09 15:51:24,539 django.request ERROR    Internal Server Error: /api/v1/ratings/7dfdc7d1-7277-4ae0-aefb-65ce687830a2/
Traceback (most recent call last):
  File "C:\Users\nazim\Desktop\estate-src\env\lib\site-packages\django\core\handlers\exception.py", line 47, in inner
    response = get_response(request)
  File "C:\Users\nazim\Desktop\estate-src\env\lib\site-packages\django\core\handlers\base.py", line 181, in _get_response
    response = wrapped_callback(request, *callback_args, **callback_kwargs)
  File "C:\Users\nazim\Desktop\estate-src\env\lib\site-packages\django\views\decorators\csrf.py", line 54, in wrapped_view
    return view_func(*args, **kwargs)
  File "C:\Users\nazim\Desktop\estate-src\env\lib\site-packages\django\views\generic\base.py", line 69, in view
    return self.dispatch(request, *args, **kwargs)
  File "C:\Users\nazim\Desktop\estate-src\env\lib\site-packages\rest_framework\views.py", line 509, in dispatch
    response = self.handle_exception(exc)
  File "C:\Users\nazim\Desktop\estate-src\env\lib\site-packages\rest_framework\views.py", line 469, in handle_exception
    self.raise_uncaught_exception(exc)
  File "C:\Users\nazim\Desktop\estate-src\env\lib\site-packages\rest_framework\views.py", line 480, in raise_uncaught_exception
    raise exc
  File "C:\Users\nazim\Desktop\estate-src\env\lib\site-packages\rest_framework\views.py", line 506, in dispatch
    response = handler(request, *args, **kwargs)
  File "C:\Users\nazim\Desktop\estate-src\env\lib\site-packages\rest_framework\decorators.py", line 50, in handler
    return func(*args, **kwargs)
  File "C:\Users\nazim\Desktop\estate-src\apps\ratings\views.py", line 16, in create_agent_review
    agent_profile = Profile.objects.get(id=profile_id, is_agent=True)
  File "C:\Users\nazim\Desktop\estate-src\env\lib\site-packages\django\db\models\manager.py", line 85, in manager_method
    return getattr(self.get_queryset(), name)(*args, **kwargs)
  File "C:\Users\nazim\Desktop\estate-src\env\lib\site-packages\django\db\models\query.py", line 439, in get
    raise self.model.DoesNotExist(
apps.profiles.models.Profile.DoesNotExist: Profile matching query does not exist.
2022-01-09 16:16:54,457 django.utils.autoreload INFO     Watching for file changes with StatReloader
2022-01-09 16:16:57,227 django.request WARNING  Not Found: /
2022-01-09 16:18:26,162 django.request ERROR    Internal Server Error: /supersecret/users/user/
Traceback (most recent call last):
  File "C:\Users\nazim\Desktop\estate-src\env\lib\site-packages\django\db\models\fields\__init__.py", line 1822, in get_prep_value
    return int(value)
ValueError: invalid literal for int() with base 10: ''

The above exception was the direct cause of the following exception:

Traceback (most recent call last):
  File "C:\Users\nazim\Desktop\estate-src\env\lib\site-packages\django\core\handlers\exception.py", line 47, in inner
    response = get_response(request)
  File "C:\Users\nazim\Desktop\estate-src\env\lib\site-packages\django\core\handlers\base.py", line 181, in _get_response
    response = wrapped_callback(request, *callback_args, **callback_kwargs)
  File "C:\Users\nazim\Desktop\estate-src\env\lib\site-packages\django\contrib\admin\options.py", line 622, in wrapper
    return self.admin_site.admin_view(view)(*args, **kwargs)
  File "C:\Users\nazim\Desktop\estate-src\env\lib\site-packages\django\utils\decorators.py", line 130, in _wrapped_view
    response = view_func(request, *args, **kwargs)
  File "C:\Users\nazim\Desktop\estate-src\env\lib\site-packages\django\views\decorators\cache.py", line 57, in _wrapped_view_func
    response = view_func(request, *args, **kwargs)
  File "C:\Users\nazim\Desktop\estate-src\env\lib\site-packages\django\contrib\admin\sites.py", line 236, in inner
    return view(request, *args, **kwargs)
  File "C:\Users\nazim\Desktop\estate-src\env\lib\site-packages\django\utils\decorators.py", line 43, in _wrapper
    return bound_method(*args, **kwargs)
  File "C:\Users\nazim\Desktop\estate-src\env\lib\site-packages\django\utils\decorators.py", line 130, in _wrapped_view
    response = view_func(request, *args, **kwargs)
  File "C:\Users\nazim\Desktop\estate-src\env\lib\site-packages\django\contrib\admin\options.py", line 1752, in changelist_view
    response = self.response_action(request, queryset=cl.get_queryset(request))
  File "C:\Users\nazim\Desktop\estate-src\env\lib\site-packages\django\contrib\admin\options.py", line 1415, in response_action
    queryset = queryset.filter(pk__in=selected)
  File "C:\Users\nazim\Desktop\estate-src\env\lib\site-packages\django\db\models\query.py", line 974, in filter
    return self._filter_or_exclude(False, args, kwargs)
  File "C:\Users\nazim\Desktop\estate-src\env\lib\site-packages\django\db\models\query.py", line 992, in _filter_or_exclude
    clone._filter_or_exclude_inplace(negate, args, kwargs)
  File "C:\Users\nazim\Desktop\estate-src\env\lib\site-packages\django\db\models\query.py", line 999, in _filter_or_exclude_inplace
    self._query.add_q(Q(*args, **kwargs))
  File "C:\Users\nazim\Desktop\estate-src\env\lib\site-packages\django\db\models\sql\query.py", line 1375, in add_q
    clause, _ = self._add_q(q_object, self.used_aliases)
  File "C:\Users\nazim\Desktop\estate-src\env\lib\site-packages\django\db\models\sql\query.py", line 1396, in _add_q
    child_clause, needed_inner = self.build_filter(
  File "C:\Users\nazim\Desktop\estate-src\env\lib\site-packages\django\db\models\sql\query.py", line 1329, in build_filter
    condition = self.build_lookup(lookups, col, value)
  File "C:\Users\nazim\Desktop\estate-src\env\lib\site-packages\django\db\models\sql\query.py", line 1180, in build_lookup
    lookup = lookup_class(lhs, rhs)
  File "C:\Users\nazim\Desktop\estate-src\env\lib\site-packages\django\db\models\lookups.py", line 22, in __init__
    self.rhs = self.get_prep_lookup()
  File "C:\Users\nazim\Desktop\estate-src\env\lib\site-packages\django\db\models\lookups.py", line 256, in get_prep_lookup
    rhs_value = self.lhs.output_field.get_prep_value(rhs_value)
  File "C:\Users\nazim\Desktop\estate-src\env\lib\site-packages\django\db\models\fields\__init__.py", line 1824, in get_prep_value
    raise e.__class__(
ValueError: Field 'pkid' expected a number but got ''.
2022-01-09 16:18:37,317 django.request ERROR    Internal Server Error: /supersecret/users/user/
Traceback (most recent call last):
  File "C:\Users\nazim\Desktop\estate-src\env\lib\site-packages\django\db\models\fields\__init__.py", line 1822, in get_prep_value
    return int(value)
ValueError: invalid literal for int() with base 10: ''

The above exception was the direct cause of the following exception:

Traceback (most recent call last):
  File "C:\Users\nazim\Desktop\estate-src\env\lib\site-packages\django\core\handlers\exception.py", line 47, in inner
    response = get_response(request)
  File "C:\Users\nazim\Desktop\estate-src\env\lib\site-packages\django\core\handlers\base.py", line 181, in _get_response
    response = wrapped_callback(request, *callback_args, **callback_kwargs)
  File "C:\Users\nazim\Desktop\estate-src\env\lib\site-packages\django\contrib\admin\options.py", line 622, in wrapper
    return self.admin_site.admin_view(view)(*args, **kwargs)
  File "C:\Users\nazim\Desktop\estate-src\env\lib\site-packages\django\utils\decorators.py", line 130, in _wrapped_view
    response = view_func(request, *args, **kwargs)
  File "C:\Users\nazim\Desktop\estate-src\env\lib\site-packages\django\views\decorators\cache.py", line 57, in _wrapped_view_func
    response = view_func(request, *args, **kwargs)
  File "C:\Users\nazim\Desktop\estate-src\env\lib\site-packages\django\contrib\admin\sites.py", line 236, in inner
    return view(request, *args, **kwargs)
  File "C:\Users\nazim\Desktop\estate-src\env\lib\site-packages\django\utils\decorators.py", line 43, in _wrapper
    return bound_method(*args, **kwargs)
  File "C:\Users\nazim\Desktop\estate-src\env\lib\site-packages\django\utils\decorators.py", line 130, in _wrapped_view
    response = view_func(request, *args, **kwargs)
  File "C:\Users\nazim\Desktop\estate-src\env\lib\site-packages\django\contrib\admin\options.py", line 1752, in changelist_view
    response = self.response_action(request, queryset=cl.get_queryset(request))
  File "C:\Users\nazim\Desktop\estate-src\env\lib\site-packages\django\contrib\admin\options.py", line 1415, in response_action
    queryset = queryset.filter(pk__in=selected)
  File "C:\Users\nazim\Desktop\estate-src\env\lib\site-packages\django\db\models\query.py", line 974, in filter
    return self._filter_or_exclude(False, args, kwargs)
  File "C:\Users\nazim\Desktop\estate-src\env\lib\site-packages\django\db\models\query.py", line 992, in _filter_or_exclude
    clone._filter_or_exclude_inplace(negate, args, kwargs)
  File "C:\Users\nazim\Desktop\estate-src\env\lib\site-packages\django\db\models\query.py", line 999, in _filter_or_exclude_inplace
    self._query.add_q(Q(*args, **kwargs))
  File "C:\Users\nazim\Desktop\estate-src\env\lib\site-packages\django\db\models\sql\query.py", line 1375, in add_q
    clause, _ = self._add_q(q_object, self.used_aliases)
  File "C:\Users\nazim\Desktop\estate-src\env\lib\site-packages\django\db\models\sql\query.py", line 1396, in _add_q
    child_clause, needed_inner = self.build_filter(
  File "C:\Users\nazim\Desktop\estate-src\env\lib\site-packages\django\db\models\sql\query.py", line 1329, in build_filter
    condition = self.build_lookup(lookups, col, value)
  File "C:\Users\nazim\Desktop\estate-src\env\lib\site-packages\django\db\models\sql\query.py", line 1180, in build_lookup
    lookup = lookup_class(lhs, rhs)
  File "C:\Users\nazim\Desktop\estate-src\env\lib\site-packages\django\db\models\lookups.py", line 22, in __init__
    self.rhs = self.get_prep_lookup()
  File "C:\Users\nazim\Desktop\estate-src\env\lib\site-packages\django\db\models\lookups.py", line 256, in get_prep_lookup
    rhs_value = self.lhs.output_field.get_prep_value(rhs_value)
  File "C:\Users\nazim\Desktop\estate-src\env\lib\site-packages\django\db\models\fields\__init__.py", line 1824, in get_prep_value
    raise e.__class__(
ValueError: Field 'pkid' expected a number but got ''.
2022-01-09 16:19:26,864 django.request ERROR    Internal Server Error: /supersecret/users/user/
Traceback (most recent call last):
  File "C:\Users\nazim\Desktop\estate-src\env\lib\site-packages\django\db\models\fields\__init__.py", line 1822, in get_prep_value
    return int(value)
ValueError: invalid literal for int() with base 10: ''

The above exception was the direct cause of the following exception:

Traceback (most recent call last):
  File "C:\Users\nazim\Desktop\estate-src\env\lib\site-packages\django\core\handlers\exception.py", line 47, in inner
    response = get_response(request)
  File "C:\Users\nazim\Desktop\estate-src\env\lib\site-packages\django\core\handlers\base.py", line 181, in _get_response
    response = wrapped_callback(request, *callback_args, **callback_kwargs)
  File "C:\Users\nazim\Desktop\estate-src\env\lib\site-packages\django\contrib\admin\options.py", line 622, in wrapper
    return self.admin_site.admin_view(view)(*args, **kwargs)
  File "C:\Users\nazim\Desktop\estate-src\env\lib\site-packages\django\utils\decorators.py", line 130, in _wrapped_view
    response = view_func(request, *args, **kwargs)
  File "C:\Users\nazim\Desktop\estate-src\env\lib\site-packages\django\views\decorators\cache.py", line 57, in _wrapped_view_func
    response = view_func(request, *args, **kwargs)
  File "C:\Users\nazim\Desktop\estate-src\env\lib\site-packages\django\contrib\admin\sites.py", line 236, in inner
    return view(request, *args, **kwargs)
  File "C:\Users\nazim\Desktop\estate-src\env\lib\site-packages\django\utils\decorators.py", line 43, in _wrapper
    return bound_method(*args, **kwargs)
  File "C:\Users\nazim\Desktop\estate-src\env\lib\site-packages\django\utils\decorators.py", line 130, in _wrapped_view
    response = view_func(request, *args, **kwargs)
  File "C:\Users\nazim\Desktop\estate-src\env\lib\site-packages\django\contrib\admin\options.py", line 1752, in changelist_view
    response = self.response_action(request, queryset=cl.get_queryset(request))
  File "C:\Users\nazim\Desktop\estate-src\env\lib\site-packages\django\contrib\admin\options.py", line 1415, in response_action
    queryset = queryset.filter(pk__in=selected)
  File "C:\Users\nazim\Desktop\estate-src\env\lib\site-packages\django\db\models\query.py", line 974, in filter
    return self._filter_or_exclude(False, args, kwargs)
  File "C:\Users\nazim\Desktop\estate-src\env\lib\site-packages\django\db\models\query.py", line 992, in _filter_or_exclude
    clone._filter_or_exclude_inplace(negate, args, kwargs)
  File "C:\Users\nazim\Desktop\estate-src\env\lib\site-packages\django\db\models\query.py", line 999, in _filter_or_exclude_inplace
    self._query.add_q(Q(*args, **kwargs))
  File "C:\Users\nazim\Desktop\estate-src\env\lib\site-packages\django\db\models\sql\query.py", line 1375, in add_q
    clause, _ = self._add_q(q_object, self.used_aliases)
  File "C:\Users\nazim\Desktop\estate-src\env\lib\site-packages\django\db\models\sql\query.py", line 1396, in _add_q
    child_clause, needed_inner = self.build_filter(
  File "C:\Users\nazim\Desktop\estate-src\env\lib\site-packages\django\db\models\sql\query.py", line 1329, in build_filter
    condition = self.build_lookup(lookups, col, value)
  File "C:\Users\nazim\Desktop\estate-src\env\lib\site-packages\django\db\models\sql\query.py", line 1180, in build_lookup
    lookup = lookup_class(lhs, rhs)
  File "C:\Users\nazim\Desktop\estate-src\env\lib\site-packages\django\db\models\lookups.py", line 22, in __init__
    self.rhs = self.get_prep_lookup()
  File "C:\Users\nazim\Desktop\estate-src\env\lib\site-packages\django\db\models\lookups.py", line 256, in get_prep_lookup
    rhs_value = self.lhs.output_field.get_prep_value(rhs_value)
  File "C:\Users\nazim\Desktop\estate-src\env\lib\site-packages\django\db\models\fields\__init__.py", line 1824, in get_prep_value
    raise e.__class__(
ValueError: Field 'pkid' expected a number but got ''.
2022-01-09 16:19:30,810 django.request ERROR    Internal Server Error: /supersecret/users/user/
Traceback (most recent call last):
  File "C:\Users\nazim\Desktop\estate-src\env\lib\site-packages\django\db\models\fields\__init__.py", line 1822, in get_prep_value
    return int(value)
ValueError: invalid literal for int() with base 10: ''

The above exception was the direct cause of the following exception:

Traceback (most recent call last):
  File "C:\Users\nazim\Desktop\estate-src\env\lib\site-packages\django\core\handlers\exception.py", line 47, in inner
    response = get_response(request)
  File "C:\Users\nazim\Desktop\estate-src\env\lib\site-packages\django\core\handlers\base.py", line 181, in _get_response
    response = wrapped_callback(request, *callback_args, **callback_kwargs)
  File "C:\Users\nazim\Desktop\estate-src\env\lib\site-packages\django\contrib\admin\options.py", line 622, in wrapper
    return self.admin_site.admin_view(view)(*args, **kwargs)
  File "C:\Users\nazim\Desktop\estate-src\env\lib\site-packages\django\utils\decorators.py", line 130, in _wrapped_view
    response = view_func(request, *args, **kwargs)
  File "C:\Users\nazim\Desktop\estate-src\env\lib\site-packages\django\views\decorators\cache.py", line 57, in _wrapped_view_func
    response = view_func(request, *args, **kwargs)
  File "C:\Users\nazim\Desktop\estate-src\env\lib\site-packages\django\contrib\admin\sites.py", line 236, in inner
    return view(request, *args, **kwargs)
  File "C:\Users\nazim\Desktop\estate-src\env\lib\site-packages\django\utils\decorators.py", line 43, in _wrapper
    return bound_method(*args, **kwargs)
  File "C:\Users\nazim\Desktop\estate-src\env\lib\site-packages\django\utils\decorators.py", line 130, in _wrapped_view
    response = view_func(request, *args, **kwargs)
  File "C:\Users\nazim\Desktop\estate-src\env\lib\site-packages\django\contrib\admin\options.py", line 1752, in changelist_view
    response = self.response_action(request, queryset=cl.get_queryset(request))
  File "C:\Users\nazim\Desktop\estate-src\env\lib\site-packages\django\contrib\admin\options.py", line 1415, in response_action
    queryset = queryset.filter(pk__in=selected)
  File "C:\Users\nazim\Desktop\estate-src\env\lib\site-packages\django\db\models\query.py", line 974, in filter
    return self._filter_or_exclude(False, args, kwargs)
  File "C:\Users\nazim\Desktop\estate-src\env\lib\site-packages\django\db\models\query.py", line 992, in _filter_or_exclude
    clone._filter_or_exclude_inplace(negate, args, kwargs)
  File "C:\Users\nazim\Desktop\estate-src\env\lib\site-packages\django\db\models\query.py", line 999, in _filter_or_exclude_inplace
    self._query.add_q(Q(*args, **kwargs))
  File "C:\Users\nazim\Desktop\estate-src\env\lib\site-packages\django\db\models\sql\query.py", line 1375, in add_q
    clause, _ = self._add_q(q_object, self.used_aliases)
  File "C:\Users\nazim\Desktop\estate-src\env\lib\site-packages\django\db\models\sql\query.py", line 1396, in _add_q
    child_clause, needed_inner = self.build_filter(
  File "C:\Users\nazim\Desktop\estate-src\env\lib\site-packages\django\db\models\sql\query.py", line 1329, in build_filter
    condition = self.build_lookup(lookups, col, value)
  File "C:\Users\nazim\Desktop\estate-src\env\lib\site-packages\django\db\models\sql\query.py", line 1180, in build_lookup
    lookup = lookup_class(lhs, rhs)
  File "C:\Users\nazim\Desktop\estate-src\env\lib\site-packages\django\db\models\lookups.py", line 22, in __init__
    self.rhs = self.get_prep_lookup()
  File "C:\Users\nazim\Desktop\estate-src\env\lib\site-packages\django\db\models\lookups.py", line 256, in get_prep_lookup
    rhs_value = self.lhs.output_field.get_prep_value(rhs_value)
  File "C:\Users\nazim\Desktop\estate-src\env\lib\site-packages\django\db\models\fields\__init__.py", line 1824, in get_prep_value
    raise e.__class__(
ValueError: Field 'pkid' expected a number but got ''.
2022-01-09 16:21:23,952 django.request WARNING  Unauthorized: /api/v1/auth/users/
2022-01-09 16:22:04,210 django.request ERROR    Internal Server Error: /supersecret/users/user/
Traceback (most recent call last):
  File "C:\Users\nazim\Desktop\estate-src\env\lib\site-packages\django\db\models\fields\__init__.py", line 1822, in get_prep_value
    return int(value)
ValueError: invalid literal for int() with base 10: ''

The above exception was the direct cause of the following exception:

Traceback (most recent call last):
  File "C:\Users\nazim\Desktop\estate-src\env\lib\site-packages\django\core\handlers\exception.py", line 47, in inner
    response = get_response(request)
  File "C:\Users\nazim\Desktop\estate-src\env\lib\site-packages\django\core\handlers\base.py", line 181, in _get_response
    response = wrapped_callback(request, *callback_args, **callback_kwargs)
  File "C:\Users\nazim\Desktop\estate-src\env\lib\site-packages\django\contrib\admin\options.py", line 622, in wrapper
    return self.admin_site.admin_view(view)(*args, **kwargs)
  File "C:\Users\nazim\Desktop\estate-src\env\lib\site-packages\django\utils\decorators.py", line 130, in _wrapped_view
    response = view_func(request, *args, **kwargs)
  File "C:\Users\nazim\Desktop\estate-src\env\lib\site-packages\django\views\decorators\cache.py", line 57, in _wrapped_view_func
    response = view_func(request, *args, **kwargs)
  File "C:\Users\nazim\Desktop\estate-src\env\lib\site-packages\django\contrib\admin\sites.py", line 236, in inner
    return view(request, *args, **kwargs)
  File "C:\Users\nazim\Desktop\estate-src\env\lib\site-packages\django\utils\decorators.py", line 43, in _wrapper
    return bound_method(*args, **kwargs)
  File "C:\Users\nazim\Desktop\estate-src\env\lib\site-packages\django\utils\decorators.py", line 130, in _wrapped_view
    response = view_func(request, *args, **kwargs)
  File "C:\Users\nazim\Desktop\estate-src\env\lib\site-packages\django\contrib\admin\options.py", line 1752, in changelist_view
    response = self.response_action(request, queryset=cl.get_queryset(request))
  File "C:\Users\nazim\Desktop\estate-src\env\lib\site-packages\django\contrib\admin\options.py", line 1415, in response_action
    queryset = queryset.filter(pk__in=selected)
  File "C:\Users\nazim\Desktop\estate-src\env\lib\site-packages\django\db\models\query.py", line 974, in filter
    return self._filter_or_exclude(False, args, kwargs)
  File "C:\Users\nazim\Desktop\estate-src\env\lib\site-packages\django\db\models\query.py", line 992, in _filter_or_exclude
    clone._filter_or_exclude_inplace(negate, args, kwargs)
  File "C:\Users\nazim\Desktop\estate-src\env\lib\site-packages\django\db\models\query.py", line 999, in _filter_or_exclude_inplace
    self._query.add_q(Q(*args, **kwargs))
  File "C:\Users\nazim\Desktop\estate-src\env\lib\site-packages\django\db\models\sql\query.py", line 1375, in add_q
    clause, _ = self._add_q(q_object, self.used_aliases)
  File "C:\Users\nazim\Desktop\estate-src\env\lib\site-packages\django\db\models\sql\query.py", line 1396, in _add_q
    child_clause, needed_inner = self.build_filter(
  File "C:\Users\nazim\Desktop\estate-src\env\lib\site-packages\django\db\models\sql\query.py", line 1329, in build_filter
    condition = self.build_lookup(lookups, col, value)
  File "C:\Users\nazim\Desktop\estate-src\env\lib\site-packages\django\db\models\sql\query.py", line 1180, in build_lookup
    lookup = lookup_class(lhs, rhs)
  File "C:\Users\nazim\Desktop\estate-src\env\lib\site-packages\django\db\models\lookups.py", line 22, in __init__
    self.rhs = self.get_prep_lookup()
  File "C:\Users\nazim\Desktop\estate-src\env\lib\site-packages\django\db\models\lookups.py", line 256, in get_prep_lookup
    rhs_value = self.lhs.output_field.get_prep_value(rhs_value)
  File "C:\Users\nazim\Desktop\estate-src\env\lib\site-packages\django\db\models\fields\__init__.py", line 1824, in get_prep_value
    raise e.__class__(
ValueError: Field 'pkid' expected a number but got ''.
2022-01-09 16:22:52,173 django.request WARNING  Not Found: /api/v1/auth/jwt/activate/
2022-01-09 16:24:20,214 django.request WARNING  Not Found: /api/v1/auth/jwt/activation/
2022-01-09 16:27:12,436 django.request ERROR    Internal Server Error: /api/v1/ratings/22296f1b-dec8-4607-aa64-8bc34af0e90c/
Traceback (most recent call last):
  File "C:\Users\nazim\Desktop\estate-src\env\lib\site-packages\django\core\handlers\exception.py", line 47, in inner
    response = get_response(request)
  File "C:\Users\nazim\Desktop\estate-src\env\lib\site-packages\django\core\handlers\base.py", line 181, in _get_response
    response = wrapped_callback(request, *callback_args, **callback_kwargs)
  File "C:\Users\nazim\Desktop\estate-src\env\lib\site-packages\django\views\decorators\csrf.py", line 54, in wrapped_view
    return view_func(*args, **kwargs)
  File "C:\Users\nazim\Desktop\estate-src\env\lib\site-packages\django\views\generic\base.py", line 69, in view
    return self.dispatch(request, *args, **kwargs)
  File "C:\Users\nazim\Desktop\estate-src\env\lib\site-packages\rest_framework\views.py", line 509, in dispatch
    response = self.handle_exception(exc)
  File "C:\Users\nazim\Desktop\estate-src\env\lib\site-packages\rest_framework\views.py", line 469, in handle_exception
    self.raise_uncaught_exception(exc)
  File "C:\Users\nazim\Desktop\estate-src\env\lib\site-packages\rest_framework\views.py", line 480, in raise_uncaught_exception
    raise exc
  File "C:\Users\nazim\Desktop\estate-src\env\lib\site-packages\rest_framework\views.py", line 506, in dispatch
    response = handler(request, *args, **kwargs)
  File "C:\Users\nazim\Desktop\estate-src\env\lib\site-packages\rest_framework\decorators.py", line 50, in handler
    return func(*args, **kwargs)
  File "C:\Users\nazim\Desktop\estate-src\apps\ratings\views.py", line 16, in create_agent_review
    agent_profile = Profile.objects.get(id=profile_id, is_agent=True)
  File "C:\Users\nazim\Desktop\estate-src\env\lib\site-packages\django\db\models\manager.py", line 85, in manager_method
    return getattr(self.get_queryset(), name)(*args, **kwargs)
  File "C:\Users\nazim\Desktop\estate-src\env\lib\site-packages\django\db\models\query.py", line 439, in get
    raise self.model.DoesNotExist(
apps.profiles.models.Profile.DoesNotExist: Profile matching query does not exist.
2022-01-09 16:28:38,569 django.request ERROR    Internal Server Error: /api/v1/ratings/22296f1b-dec8-4607-aa64-8bc34af0e90c/
Traceback (most recent call last):
  File "C:\Users\nazim\Desktop\estate-src\env\lib\site-packages\django\core\handlers\exception.py", line 47, in inner
    response = get_response(request)
  File "C:\Users\nazim\Desktop\estate-src\env\lib\site-packages\django\core\handlers\base.py", line 181, in _get_response
    response = wrapped_callback(request, *callback_args, **callback_kwargs)
  File "C:\Users\nazim\Desktop\estate-src\env\lib\site-packages\django\views\decorators\csrf.py", line 54, in wrapped_view
    return view_func(*args, **kwargs)
  File "C:\Users\nazim\Desktop\estate-src\env\lib\site-packages\django\views\generic\base.py", line 69, in view
    return self.dispatch(request, *args, **kwargs)
  File "C:\Users\nazim\Desktop\estate-src\env\lib\site-packages\rest_framework\views.py", line 509, in dispatch
    response = self.handle_exception(exc)
  File "C:\Users\nazim\Desktop\estate-src\env\lib\site-packages\rest_framework\views.py", line 469, in handle_exception
    self.raise_uncaught_exception(exc)
  File "C:\Users\nazim\Desktop\estate-src\env\lib\site-packages\rest_framework\views.py", line 480, in raise_uncaught_exception
    raise exc
  File "C:\Users\nazim\Desktop\estate-src\env\lib\site-packages\rest_framework\views.py", line 506, in dispatch
    response = handler(request, *args, **kwargs)
  File "C:\Users\nazim\Desktop\estate-src\env\lib\site-packages\rest_framework\decorators.py", line 50, in handler
    return func(*args, **kwargs)
  File "C:\Users\nazim\Desktop\estate-src\apps\ratings\views.py", line 16, in create_agent_review
    agent_profile = Profile.objects.get(id=profile_id, is_agent=True)
  File "C:\Users\nazim\Desktop\estate-src\env\lib\site-packages\django\db\models\manager.py", line 85, in manager_method
    return getattr(self.get_queryset(), name)(*args, **kwargs)
  File "C:\Users\nazim\Desktop\estate-src\env\lib\site-packages\django\db\models\query.py", line 439, in get
    raise self.model.DoesNotExist(
apps.profiles.models.Profile.DoesNotExist: Profile matching query does not exist.
2022-01-09 16:31:25,413 django.request WARNING  Not Found: /api/v1/enquiries/22296f1b-dec8-4607-aa64-8bc34af0e90c/
2022-01-09 16:34:38,356 django.request ERROR    Internal Server Error: /supersecret/users/user/
Traceback (most recent call last):
  File "C:\Users\nazim\Desktop\estate-src\env\lib\site-packages\django\db\models\fields\__init__.py", line 1822, in get_prep_value
    return int(value)
ValueError: invalid literal for int() with base 10: ''

The above exception was the direct cause of the following exception:

Traceback (most recent call last):
  File "C:\Users\nazim\Desktop\estate-src\env\lib\site-packages\django\core\handlers\exception.py", line 47, in inner
    response = get_response(request)
  File "C:\Users\nazim\Desktop\estate-src\env\lib\site-packages\django\core\handlers\base.py", line 181, in _get_response
    response = wrapped_callback(request, *callback_args, **callback_kwargs)
  File "C:\Users\nazim\Desktop\estate-src\env\lib\site-packages\django\contrib\admin\options.py", line 622, in wrapper
    return self.admin_site.admin_view(view)(*args, **kwargs)
  File "C:\Users\nazim\Desktop\estate-src\env\lib\site-packages\django\utils\decorators.py", line 130, in _wrapped_view
    response = view_func(request, *args, **kwargs)
  File "C:\Users\nazim\Desktop\estate-src\env\lib\site-packages\django\views\decorators\cache.py", line 57, in _wrapped_view_func
    response = view_func(request, *args, **kwargs)
  File "C:\Users\nazim\Desktop\estate-src\env\lib\site-packages\django\contrib\admin\sites.py", line 236, in inner
    return view(request, *args, **kwargs)
  File "C:\Users\nazim\Desktop\estate-src\env\lib\site-packages\django\utils\decorators.py", line 43, in _wrapper
    return bound_method(*args, **kwargs)
  File "C:\Users\nazim\Desktop\estate-src\env\lib\site-packages\django\utils\decorators.py", line 130, in _wrapped_view
    response = view_func(request, *args, **kwargs)
  File "C:\Users\nazim\Desktop\estate-src\env\lib\site-packages\django\contrib\admin\options.py", line 1752, in changelist_view
    response = self.response_action(request, queryset=cl.get_queryset(request))
  File "C:\Users\nazim\Desktop\estate-src\env\lib\site-packages\django\contrib\admin\options.py", line 1415, in response_action
    queryset = queryset.filter(pk__in=selected)
  File "C:\Users\nazim\Desktop\estate-src\env\lib\site-packages\django\db\models\query.py", line 974, in filter
    return self._filter_or_exclude(False, args, kwargs)
  File "C:\Users\nazim\Desktop\estate-src\env\lib\site-packages\django\db\models\query.py", line 992, in _filter_or_exclude
    clone._filter_or_exclude_inplace(negate, args, kwargs)
  File "C:\Users\nazim\Desktop\estate-src\env\lib\site-packages\django\db\models\query.py", line 999, in _filter_or_exclude_inplace
    self._query.add_q(Q(*args, **kwargs))
  File "C:\Users\nazim\Desktop\estate-src\env\lib\site-packages\django\db\models\sql\query.py", line 1375, in add_q
    clause, _ = self._add_q(q_object, self.used_aliases)
  File "C:\Users\nazim\Desktop\estate-src\env\lib\site-packages\django\db\models\sql\query.py", line 1396, in _add_q
    child_clause, needed_inner = self.build_filter(
  File "C:\Users\nazim\Desktop\estate-src\env\lib\site-packages\django\db\models\sql\query.py", line 1329, in build_filter
    condition = self.build_lookup(lookups, col, value)
  File "C:\Users\nazim\Desktop\estate-src\env\lib\site-packages\django\db\models\sql\query.py", line 1180, in build_lookup
    lookup = lookup_class(lhs, rhs)
  File "C:\Users\nazim\Desktop\estate-src\env\lib\site-packages\django\db\models\lookups.py", line 22, in __init__
    self.rhs = self.get_prep_lookup()
  File "C:\Users\nazim\Desktop\estate-src\env\lib\site-packages\django\db\models\lookups.py", line 256, in get_prep_lookup
    rhs_value = self.lhs.output_field.get_prep_value(rhs_value)
  File "C:\Users\nazim\Desktop\estate-src\env\lib\site-packages\django\db\models\fields\__init__.py", line 1824, in get_prep_value
    raise e.__class__(
ValueError: Field 'pkid' expected a number but got ''.
2022-01-09 16:35:11,674 django.request ERROR    Internal Server Error: /supersecret/users/user/3/change/
Traceback (most recent call last):
  File "C:\Users\nazim\Desktop\estate-src\env\lib\site-packages\django\core\handlers\exception.py", line 47, in inner
    response = get_response(request)
  File "C:\Users\nazim\Desktop\estate-src\env\lib\site-packages\django\core\handlers\base.py", line 181, in _get_response
    response = wrapped_callback(request, *callback_args, **callback_kwargs)
  File "C:\Users\nazim\Desktop\estate-src\env\lib\site-packages\django\contrib\admin\options.py", line 622, in wrapper
    return self.admin_site.admin_view(view)(*args, **kwargs)
  File "C:\Users\nazim\Desktop\estate-src\env\lib\site-packages\django\utils\decorators.py", line 130, in _wrapped_view
    response = view_func(request, *args, **kwargs)
  File "C:\Users\nazim\Desktop\estate-src\env\lib\site-packages\django\views\decorators\cache.py", line 57, in _wrapped_view_func
    response = view_func(request, *args, **kwargs)
  File "C:\Users\nazim\Desktop\estate-src\env\lib\site-packages\django\contrib\admin\sites.py", line 236, in inner
    return view(request, *args, **kwargs)
  File "C:\Users\nazim\Desktop\estate-src\env\lib\site-packages\django\contrib\admin\options.py", line 1673, in change_view
    return self.changeform_view(request, object_id, form_url, extra_context)
  File "C:\Users\nazim\Desktop\estate-src\env\lib\site-packages\django\utils\decorators.py", line 43, in _wrapper
    return bound_method(*args, **kwargs)
  File "C:\Users\nazim\Desktop\estate-src\env\lib\site-packages\django\utils\decorators.py", line 130, in _wrapped_view
    response = view_func(request, *args, **kwargs)
  File "C:\Users\nazim\Desktop\estate-src\env\lib\site-packages\django\contrib\admin\options.py", line 1549, in changeform_view
    return self._changeform_view(request, object_id, form_url, extra_context)
  File "C:\Users\nazim\Desktop\estate-src\env\lib\site-packages\django\contrib\admin\options.py", line 1599, in _changeform_view
    self.save_model(request, new_object, form, not add)
  File "C:\Users\nazim\Desktop\estate-src\env\lib\site-packages\django\contrib\admin\options.py", line 1108, in save_model
    obj.save()
  File "C:\Users\nazim\Desktop\estate-src\env\lib\site-packages\django\contrib\auth\base_user.py", line 66, in save
    super().save(*args, **kwargs)
  File "C:\Users\nazim\Desktop\estate-src\env\lib\site-packages\django\db\models\base.py", line 743, in save
    self.save_base(using=using, force_insert=force_insert,
  File "C:\Users\nazim\Desktop\estate-src\env\lib\site-packages\django\db\models\base.py", line 791, in save_base
    post_save.send(
  File "C:\Users\nazim\Desktop\estate-src\env\lib\site-packages\django\dispatch\dispatcher.py", line 170, in send
    return [
  File "C:\Users\nazim\Desktop\estate-src\env\lib\site-packages\django\dispatch\dispatcher.py", line 171, in <listcomp>
    (receiver, receiver(signal=self, sender=sender, **named))
  File "C:\Users\nazim\Desktop\estate-src\apps\profiles\signals.py", line 18, in save_user_profile
    instance.profile.save()
  File "C:\Users\nazim\Desktop\estate-src\env\lib\site-packages\django\db\models\fields\related_descriptors.py", line 421, in __get__
    raise self.RelatedObjectDoesNotExist(
apps.users.models.User.profile.RelatedObjectDoesNotExist: User has no profile.
2022-01-09 16:36:22,540 django.request WARNING  Not Found: /api/v1/ratings/ e37114b1-3370-47b5-9cfa-79c0c673062/4
2022-01-09 16:36:31,316 django.request ERROR    Internal Server Error: /api/v1/ratings/ e37114b1-3370-47b5-9cfa-79c0c673062/
Traceback (most recent call last):
  File "C:\Users\nazim\Desktop\estate-src\env\lib\site-packages\django\core\handlers\exception.py", line 47, in inner
    response = get_response(request)
  File "C:\Users\nazim\Desktop\estate-src\env\lib\site-packages\django\core\handlers\base.py", line 181, in _get_response
    response = wrapped_callback(request, *callback_args, **callback_kwargs)
  File "C:\Users\nazim\Desktop\estate-src\env\lib\site-packages\django\views\decorators\csrf.py", line 54, in wrapped_view
    return view_func(*args, **kwargs)
  File "C:\Users\nazim\Desktop\estate-src\env\lib\site-packages\django\views\generic\base.py", line 69, in view
    return self.dispatch(request, *args, **kwargs)
  File "C:\Users\nazim\Desktop\estate-src\env\lib\site-packages\rest_framework\views.py", line 509, in dispatch
    response = self.handle_exception(exc)
  File "C:\Users\nazim\Desktop\estate-src\env\lib\site-packages\rest_framework\views.py", line 469, in handle_exception
    self.raise_uncaught_exception(exc)
  File "C:\Users\nazim\Desktop\estate-src\env\lib\site-packages\rest_framework\views.py", line 480, in raise_uncaught_exception
    raise exc
  File "C:\Users\nazim\Desktop\estate-src\env\lib\site-packages\rest_framework\views.py", line 506, in dispatch
    response = handler(request, *args, **kwargs)
  File "C:\Users\nazim\Desktop\estate-src\env\lib\site-packages\rest_framework\decorators.py", line 50, in handler
    return func(*args, **kwargs)
  File "C:\Users\nazim\Desktop\estate-src\apps\ratings\views.py", line 16, in create_agent_review
    agent_profile = Profile.objects.get(id=profile_id, is_agent=True)
  File "C:\Users\nazim\Desktop\estate-src\env\lib\site-packages\django\db\models\manager.py", line 85, in manager_method
    return getattr(self.get_queryset(), name)(*args, **kwargs)
  File "C:\Users\nazim\Desktop\estate-src\env\lib\site-packages\django\db\models\query.py", line 439, in get
    raise self.model.DoesNotExist(
apps.profiles.models.Profile.DoesNotExist: Profile matching query does not exist.
2022-01-09 16:36:54,536 django.request ERROR    Internal Server Error: /api/v1/ratings/2c5c8baa-c26c-411d-abbc-024299063f86/
Traceback (most recent call last):
  File "C:\Users\nazim\Desktop\estate-src\env\lib\site-packages\django\core\handlers\exception.py", line 47, in inner
    response = get_response(request)
  File "C:\Users\nazim\Desktop\estate-src\env\lib\site-packages\django\core\handlers\base.py", line 181, in _get_response
    response = wrapped_callback(request, *callback_args, **callback_kwargs)
  File "C:\Users\nazim\Desktop\estate-src\env\lib\site-packages\django\views\decorators\csrf.py", line 54, in wrapped_view
    return view_func(*args, **kwargs)
  File "C:\Users\nazim\Desktop\estate-src\env\lib\site-packages\django\views\generic\base.py", line 69, in view
    return self.dispatch(request, *args, **kwargs)
  File "C:\Users\nazim\Desktop\estate-src\env\lib\site-packages\rest_framework\views.py", line 509, in dispatch
    response = self.handle_exception(exc)
  File "C:\Users\nazim\Desktop\estate-src\env\lib\site-packages\rest_framework\views.py", line 469, in handle_exception
    self.raise_uncaught_exception(exc)
  File "C:\Users\nazim\Desktop\estate-src\env\lib\site-packages\rest_framework\views.py", line 480, in raise_uncaught_exception
    raise exc
  File "C:\Users\nazim\Desktop\estate-src\env\lib\site-packages\rest_framework\views.py", line 506, in dispatch
    response = handler(request, *args, **kwargs)
  File "C:\Users\nazim\Desktop\estate-src\env\lib\site-packages\rest_framework\decorators.py", line 50, in handler
    return func(*args, **kwargs)
  File "C:\Users\nazim\Desktop\estate-src\apps\ratings\views.py", line 16, in create_agent_review
    agent_profile = Profile.objects.get(id=profile_id, is_agent=True)
  File "C:\Users\nazim\Desktop\estate-src\env\lib\site-packages\django\db\models\manager.py", line 85, in manager_method
    return getattr(self.get_queryset(), name)(*args, **kwargs)
  File "C:\Users\nazim\Desktop\estate-src\env\lib\site-packages\django\db\models\query.py", line 439, in get
    raise self.model.DoesNotExist(
apps.profiles.models.Profile.DoesNotExist: Profile matching query does not exist.
2022-01-09 16:37:13,082 django.request ERROR    Internal Server Error: /api/v1/ratings/2c5c8baa-c26c-411d-abbc-024299063f86/
Traceback (most recent call last):
  File "C:\Users\nazim\Desktop\estate-src\env\lib\site-packages\django\core\handlers\exception.py", line 47, in inner
    response = get_response(request)
  File "C:\Users\nazim\Desktop\estate-src\env\lib\site-packages\django\core\handlers\base.py", line 181, in _get_response
    response = wrapped_callback(request, *callback_args, **callback_kwargs)
  File "C:\Users\nazim\Desktop\estate-src\env\lib\site-packages\django\views\decorators\csrf.py", line 54, in wrapped_view
    return view_func(*args, **kwargs)
  File "C:\Users\nazim\Desktop\estate-src\env\lib\site-packages\django\views\generic\base.py", line 69, in view
    return self.dispatch(request, *args, **kwargs)
  File "C:\Users\nazim\Desktop\estate-src\env\lib\site-packages\rest_framework\views.py", line 509, in dispatch
    response = self.handle_exception(exc)
  File "C:\Users\nazim\Desktop\estate-src\env\lib\site-packages\rest_framework\views.py", line 469, in handle_exception
    self.raise_uncaught_exception(exc)
  File "C:\Users\nazim\Desktop\estate-src\env\lib\site-packages\rest_framework\views.py", line 480, in raise_uncaught_exception
    raise exc
  File "C:\Users\nazim\Desktop\estate-src\env\lib\site-packages\rest_framework\views.py", line 506, in dispatch
    response = handler(request, *args, **kwargs)
  File "C:\Users\nazim\Desktop\estate-src\env\lib\site-packages\rest_framework\decorators.py", line 50, in handler
    return func(*args, **kwargs)
  File "C:\Users\nazim\Desktop\estate-src\apps\ratings\views.py", line 16, in create_agent_review
    agent_profile = Profile.objects.get(id=profile_id, is_agent=True)
  File "C:\Users\nazim\Desktop\estate-src\env\lib\site-packages\django\db\models\manager.py", line 85, in manager_method
    return getattr(self.get_queryset(), name)(*args, **kwargs)
  File "C:\Users\nazim\Desktop\estate-src\env\lib\site-packages\django\db\models\query.py", line 439, in get
    raise self.model.DoesNotExist(
apps.profiles.models.Profile.DoesNotExist: Profile matching query does not exist.
2022-01-09 16:38:08,482 django.request ERROR    Internal Server Error: /api/v1/ratings/2c5c8baa-c26c-411d-abbc-024299063f86/
Traceback (most recent call last):
  File "C:\Users\nazim\Desktop\estate-src\env\lib\site-packages\django\core\handlers\exception.py", line 47, in inner
    response = get_response(request)
  File "C:\Users\nazim\Desktop\estate-src\env\lib\site-packages\django\core\handlers\base.py", line 181, in _get_response
    response = wrapped_callback(request, *callback_args, **callback_kwargs)
  File "C:\Users\nazim\Desktop\estate-src\env\lib\site-packages\django\views\decorators\csrf.py", line 54, in wrapped_view
    return view_func(*args, **kwargs)
  File "C:\Users\nazim\Desktop\estate-src\env\lib\site-packages\django\views\generic\base.py", line 69, in view
    return self.dispatch(request, *args, **kwargs)
  File "C:\Users\nazim\Desktop\estate-src\env\lib\site-packages\rest_framework\views.py", line 509, in dispatch
    response = self.handle_exception(exc)
  File "C:\Users\nazim\Desktop\estate-src\env\lib\site-packages\rest_framework\views.py", line 469, in handle_exception
    self.raise_uncaught_exception(exc)
  File "C:\Users\nazim\Desktop\estate-src\env\lib\site-packages\rest_framework\views.py", line 480, in raise_uncaught_exception
    raise exc
  File "C:\Users\nazim\Desktop\estate-src\env\lib\site-packages\rest_framework\views.py", line 506, in dispatch
    response = handler(request, *args, **kwargs)
  File "C:\Users\nazim\Desktop\estate-src\env\lib\site-packages\rest_framework\decorators.py", line 50, in handler
    return func(*args, **kwargs)
  File "C:\Users\nazim\Desktop\estate-src\apps\ratings\views.py", line 16, in create_agent_review
    agent_profile = Profile.objects.get(id=profile_id, is_agent=True)
  File "C:\Users\nazim\Desktop\estate-src\env\lib\site-packages\django\db\models\manager.py", line 85, in manager_method
    return getattr(self.get_queryset(), name)(*args, **kwargs)
  File "C:\Users\nazim\Desktop\estate-src\env\lib\site-packages\django\db\models\query.py", line 439, in get
    raise self.model.DoesNotExist(
apps.profiles.models.Profile.DoesNotExist: Profile matching query does not exist.
2022-01-09 16:38:58,969 django.request WARNING  Forbidden: /api/v1/ratings/2c5c8baa-c26c-411d-abbc-024299063f86/
2022-01-10 11:15:06,756 django.utils.autoreload INFO     Watching for file changes with StatReloader
2022-01-10 11:41:51,673 django.utils.autoreload INFO     Watching for file changes with StatReloader
2022-01-10 11:50:05,842 django.utils.autoreload INFO     Watching for file changes with StatReloader
2022-01-10 11:53:43,814 django.utils.autoreload INFO     Watching for file changes with StatReloader
2022-01-10 11:53:47,846 django.request WARNING  Not Found: /
2022-01-10 11:53:48,002 django.request WARNING  Not Found: /favicon.ico
2022-01-10 11:53:50,847 django.request WARNING  Not Found: /admin
2022-01-10 11:57:58,048 django.utils.autoreload INFO     Watching for file changes with StatReloader
2022-01-10 12:08:51,252 django.utils.autoreload INFO     Watching for file changes with StatReloader
2022-01-10 12:11:58,588 django.utils.autoreload INFO     /app/apps/common/apps.py changed, reloading.
2022-01-10 12:12:01,054 django.utils.autoreload INFO     Watching for file changes with StatReloader
2022-01-10 12:15:44,135 django.utils.autoreload INFO     /app/apps/profiles/serializers.py changed, reloading.
2022-01-10 12:15:47,343 django.utils.autoreload INFO     Watching for file changes with StatReloader
2022-01-10 12:20:25,067 django.utils.autoreload INFO     /app/real_estate/settings/base.py changed, reloading.
2022-01-10 12:20:27,460 django.utils.autoreload INFO     Watching for file changes with StatReloader
2022-01-10 12:20:34,318 django.utils.autoreload INFO     /app/real_estate/settings/base.py changed, reloading.
2022-01-10 12:20:37,111 django.utils.autoreload INFO     Watching for file changes with StatReloader
2022-01-10 13:43:06,705 django.utils.autoreload INFO     Watching for file changes with StatReloader
2022-01-10 14:02:25,241 django.request WARNING  Not Found: /
2022-01-10 14:17:21,540 django.utils.autoreload INFO     /app/apps/users/models.py changed, reloading.
2022-01-10 14:17:24,559 django.utils.autoreload INFO     Watching for file changes with StatReloader
2022-01-11 06:26:29,318 django.utils.autoreload INFO     Watching for file changes with StatReloader
2022-01-11 06:26:41,213 django.request WARNING  Not Found: /
2022-01-11 06:26:41,312 django.request WARNING  Not Found: /favicon.ico
2022-01-11 06:27:01,549 django.request WARNING  Not Found: /
2022-01-11 06:27:03,418 django.request WARNING  Not Found: /
2022-01-11 06:28:27,396 django.request WARNING  Not Found: /
2022-01-11 06:29:53,804 django.utils.autoreload INFO     Watching for file changes with StatReloader
2022-01-11 06:30:45,615 django.utils.autoreload INFO     Watching for file changes with StatReloader
2022-01-11 06:30:56,234 django.request WARNING  Not Found: /
2022-01-11 06:35:42,223 django.utils.autoreload INFO     Watching for file changes with StatReloader
2022-01-11 06:35:52,107 django.request WARNING  Not Found: /
2022-01-11 06:35:54,594 django.request WARNING  Not Found: /
2022-01-11 06:35:55,149 django.request WARNING  Not Found: /
2022-01-11 06:39:55,741 django.utils.autoreload INFO     Watching for file changes with StatReloader
2022-01-11 06:40:38,752 django.request WARNING  Not Found: /
2022-01-11 06:41:48,876 django.request WARNING  Not Found: /api/v1/profiles
2022-01-11 06:41:54,300 django.request WARNING  Not Found: /api/v1/profile
2022-01-11 06:41:58,155 django.request WARNING  Not Found: /api/v1/profile/
2022-01-11 06:42:08,332 django.request WARNING  Not Found: /api/v1/profile/all
2022-01-11 06:42:11,683 django.request WARNING  Not Found: /api/v1/profile/all/
2022-01-11 06:42:19,735 django.request WARNING  Unauthorized: /api/v1/profile/agents/all/
2022-01-11 06:42:33,326 django.request WARNING  Not Found: /
2022-01-11 09:34:13,494 django.utils.autoreload INFO     Watching for file changes with StatReloader
2022-01-11 09:43:59,165 django.utils.autoreload INFO     Watching for file changes with StatReloader
2022-01-11 09:44:27,318 django.request WARNING  Not Found: /
2022-01-11 09:48:31,439 django.utils.autoreload INFO     Watching for file changes with StatReloader
2022-01-11 09:49:37,668 django.request WARNING  Not Found: /
2022-01-11 09:51:39,791 django.utils.autoreload INFO     /app/real_estate/settings/base.py changed, reloading.
2022-01-11 09:51:41,140 django.utils.autoreload INFO     Watching for file changes with StatReloader
2022-01-11 09:52:20,931 django.utils.autoreload INFO     Watching for file changes with StatReloader
2022-01-11 09:53:14,734 django.request WARNING  Not Found: /
2022-01-11 09:58:06,137 django.utils.autoreload INFO     Watching for file changes with StatReloader
2022-01-11 10:06:28,398 django.utils.autoreload INFO     Watching for file changes with StatReloader
2022-01-11 10:13:21,002 django.utils.autoreload INFO     Watching for file changes with StatReloader
2022-01-11 10:17:46,612 django.utils.autoreload INFO     Watching for file changes with StatReloader
2022-01-11 10:19:41,190 django.utils.autoreload INFO     Watching for file changes with StatReloader
2022-01-11 10:25:04,240 django.utils.autoreload INFO     Watching for file changes with StatReloader
2022-01-11 10:27:44,001 django.utils.autoreload INFO     Watching for file changes with StatReloader
2022-01-11 10:32:10,674 django.utils.autoreload INFO     Watching for file changes with StatReloader
2022-01-11 10:58:22,602 django.utils.autoreload INFO     Watching for file changes with StatReloader
2022-01-11 11:01:12,131 django.utils.autoreload INFO     Watching for file changes with StatReloader
2022-01-11 11:03:48,671 django.utils.autoreload INFO     Watching for file changes with StatReloader
2022-01-11 11:04:53,676 flower.command WARNING  You have incorrectly specified the following celery arguments after flower command: ['--broker']. Please specify them after celery command instead following this template: celery [celery args] flower [flower args].
2022-01-11 11:04:54,582 flower.command INFO     Visit me at http://localhost:5555
2022-01-11 11:04:54,592 flower.command INFO     Broker: redis://redis:6379/0
2022-01-11 11:04:54,600 flower.command INFO     Registered tasks: 
['celery.accumulate',
 'celery.backend_cleanup',
 'celery.chain',
 'celery.chord',
 'celery.chord_unlock',
 'celery.chunks',
 'celery.group',
 'celery.map',
 'celery.starmap',
 'djcelery_email_send_multiple']
2022-01-11 11:04:54,603 kombu.mixins INFO     Connected to redis://redis:6379/0
2022-01-11 11:04:55,659 flower.inspector WARNING  Inspect method registered failed
2022-01-11 11:04:55,663 flower.inspector WARNING  Inspect method active_queues failed
2022-01-11 11:04:55,666 flower.inspector WARNING  Inspect method scheduled failed
2022-01-11 11:04:55,670 flower.inspector WARNING  Inspect method reserved failed
2022-01-11 11:04:55,671 flower.inspector WARNING  Inspect method active failed
2022-01-11 11:04:55,679 flower.inspector WARNING  Inspect method stats failed
2022-01-11 11:04:57,205 flower.inspector WARNING  Inspect method conf failed
2022-01-11 11:04:57,307 flower.inspector WARNING  Inspect method revoked failed
2022-01-11 11:04:57,589 django.utils.autoreload INFO     Watching for file changes with StatReloader
2022-01-11 11:07:49,913 django.request WARNING  Unauthorized: /api/v1/auth/jwt/create/
2022-01-11 11:08:25,728 django.request ERROR    Internal Server Error: /api/v1/auth/users/
Traceback (most recent call last):
  File "/usr/local/lib/python3.10/site-packages/django/core/handlers/exception.py", line 47, in inner
    response = get_response(request)
  File "/usr/local/lib/python3.10/site-packages/django/core/handlers/base.py", line 181, in _get_response
    response = wrapped_callback(request, *callback_args, **callback_kwargs)
  File "/usr/local/lib/python3.10/site-packages/django/views/decorators/csrf.py", line 54, in wrapped_view
    return view_func(*args, **kwargs)
  File "/usr/local/lib/python3.10/site-packages/rest_framework/viewsets.py", line 125, in view
    return self.dispatch(request, *args, **kwargs)
  File "/usr/local/lib/python3.10/site-packages/rest_framework/views.py", line 509, in dispatch
    response = self.handle_exception(exc)
  File "/usr/local/lib/python3.10/site-packages/rest_framework/views.py", line 469, in handle_exception
    self.raise_uncaught_exception(exc)
  File "/usr/local/lib/python3.10/site-packages/rest_framework/views.py", line 480, in raise_uncaught_exception
    raise exc
  File "/usr/local/lib/python3.10/site-packages/rest_framework/views.py", line 506, in dispatch
    response = handler(request, *args, **kwargs)
  File "/usr/local/lib/python3.10/site-packages/rest_framework/mixins.py", line 46, in list
    return Response(serializer.data)
  File "/usr/local/lib/python3.10/site-packages/rest_framework/serializers.py", line 768, in data
    ret = super().data
  File "/usr/local/lib/python3.10/site-packages/rest_framework/serializers.py", line 253, in data
    self._data = self.to_representation(self.instance)
  File "/usr/local/lib/python3.10/site-packages/rest_framework/serializers.py", line 686, in to_representation
    return [
  File "/usr/local/lib/python3.10/site-packages/rest_framework/serializers.py", line 687, in <listcomp>
    self.child.to_representation(item) for item in iterable
  File "/app/apps/users/serializers.py", line 45, in to_representation
    representation = super(UserSerializer, self).to_representation(instance)
  File "/usr/local/lib/python3.10/site-packages/rest_framework/serializers.py", line 522, in to_representation
    ret[field.field_name] = field.to_representation(attribute)
  File "/usr/local/lib/python3.10/site-packages/rest_framework/fields.py", line 1885, in to_representation
    method = getattr(self.parent, self.method_name)
AttributeError: 'UserSerializer' object has no attribute 'get_full_name'
2022-01-11 11:08:35,391 django.request ERROR    Internal Server Error: /api/v1/auth/users/
Traceback (most recent call last):
  File "/usr/local/lib/python3.10/site-packages/django/core/handlers/exception.py", line 47, in inner
    response = get_response(request)
  File "/usr/local/lib/python3.10/site-packages/django/core/handlers/base.py", line 181, in _get_response
    response = wrapped_callback(request, *callback_args, **callback_kwargs)
  File "/usr/local/lib/python3.10/site-packages/django/views/decorators/csrf.py", line 54, in wrapped_view
    return view_func(*args, **kwargs)
  File "/usr/local/lib/python3.10/site-packages/rest_framework/viewsets.py", line 125, in view
    return self.dispatch(request, *args, **kwargs)
  File "/usr/local/lib/python3.10/site-packages/rest_framework/views.py", line 509, in dispatch
    response = self.handle_exception(exc)
  File "/usr/local/lib/python3.10/site-packages/rest_framework/views.py", line 469, in handle_exception
    self.raise_uncaught_exception(exc)
  File "/usr/local/lib/python3.10/site-packages/rest_framework/views.py", line 480, in raise_uncaught_exception
    raise exc
  File "/usr/local/lib/python3.10/site-packages/rest_framework/views.py", line 506, in dispatch
    response = handler(request, *args, **kwargs)
  File "/usr/local/lib/python3.10/site-packages/rest_framework/mixins.py", line 46, in list
    return Response(serializer.data)
  File "/usr/local/lib/python3.10/site-packages/rest_framework/serializers.py", line 768, in data
    ret = super().data
  File "/usr/local/lib/python3.10/site-packages/rest_framework/serializers.py", line 253, in data
    self._data = self.to_representation(self.instance)
  File "/usr/local/lib/python3.10/site-packages/rest_framework/serializers.py", line 686, in to_representation
    return [
  File "/usr/local/lib/python3.10/site-packages/rest_framework/serializers.py", line 687, in <listcomp>
    self.child.to_representation(item) for item in iterable
  File "/app/apps/users/serializers.py", line 45, in to_representation
    representation = super(UserSerializer, self).to_representation(instance)
  File "/usr/local/lib/python3.10/site-packages/rest_framework/serializers.py", line 522, in to_representation
    ret[field.field_name] = field.to_representation(attribute)
  File "/usr/local/lib/python3.10/site-packages/rest_framework/fields.py", line 1885, in to_representation
    method = getattr(self.parent, self.method_name)
AttributeError: 'UserSerializer' object has no attribute 'get_full_name'
2022-01-11 11:08:58,185 django.request ERROR    Internal Server Error: /api/v1/auth/users/me/
Traceback (most recent call last):
  File "/usr/local/lib/python3.10/site-packages/django/core/handlers/exception.py", line 47, in inner
    response = get_response(request)
  File "/usr/local/lib/python3.10/site-packages/django/core/handlers/base.py", line 181, in _get_response
    response = wrapped_callback(request, *callback_args, **callback_kwargs)
  File "/usr/local/lib/python3.10/site-packages/django/views/decorators/csrf.py", line 54, in wrapped_view
    return view_func(*args, **kwargs)
  File "/usr/local/lib/python3.10/site-packages/rest_framework/viewsets.py", line 125, in view
    return self.dispatch(request, *args, **kwargs)
  File "/usr/local/lib/python3.10/site-packages/rest_framework/views.py", line 509, in dispatch
    response = self.handle_exception(exc)
  File "/usr/local/lib/python3.10/site-packages/rest_framework/views.py", line 469, in handle_exception
    self.raise_uncaught_exception(exc)
  File "/usr/local/lib/python3.10/site-packages/rest_framework/views.py", line 480, in raise_uncaught_exception
    raise exc
  File "/usr/local/lib/python3.10/site-packages/rest_framework/views.py", line 506, in dispatch
    response = handler(request, *args, **kwargs)
  File "/usr/local/lib/python3.10/site-packages/djoser/views.py", line 171, in me
    return self.retrieve(request, *args, **kwargs)
  File "/usr/local/lib/python3.10/site-packages/rest_framework/mixins.py", line 56, in retrieve
    return Response(serializer.data)
  File "/usr/local/lib/python3.10/site-packages/rest_framework/serializers.py", line 555, in data
    ret = super().data
  File "/usr/local/lib/python3.10/site-packages/rest_framework/serializers.py", line 253, in data
    self._data = self.to_representation(self.instance)
  File "/app/apps/users/serializers.py", line 45, in to_representation
    representation = super(UserSerializer, self).to_representation(instance)
  File "/usr/local/lib/python3.10/site-packages/rest_framework/serializers.py", line 522, in to_representation
    ret[field.field_name] = field.to_representation(attribute)
  File "/usr/local/lib/python3.10/site-packages/rest_framework/fields.py", line 1885, in to_representation
    method = getattr(self.parent, self.method_name)
AttributeError: 'UserSerializer' object has no attribute 'get_full_name'
2022-01-11 11:09:01,196 django.request ERROR    Internal Server Error: /api/v1/auth/users/me/
Traceback (most recent call last):
  File "/usr/local/lib/python3.10/site-packages/django/core/handlers/exception.py", line 47, in inner
    response = get_response(request)
  File "/usr/local/lib/python3.10/site-packages/django/core/handlers/base.py", line 181, in _get_response
    response = wrapped_callback(request, *callback_args, **callback_kwargs)
  File "/usr/local/lib/python3.10/site-packages/django/views/decorators/csrf.py", line 54, in wrapped_view
    return view_func(*args, **kwargs)
  File "/usr/local/lib/python3.10/site-packages/rest_framework/viewsets.py", line 125, in view
    return self.dispatch(request, *args, **kwargs)
  File "/usr/local/lib/python3.10/site-packages/rest_framework/views.py", line 509, in dispatch
    response = self.handle_exception(exc)
  File "/usr/local/lib/python3.10/site-packages/rest_framework/views.py", line 469, in handle_exception
    self.raise_uncaught_exception(exc)
  File "/usr/local/lib/python3.10/site-packages/rest_framework/views.py", line 480, in raise_uncaught_exception
    raise exc
  File "/usr/local/lib/python3.10/site-packages/rest_framework/views.py", line 506, in dispatch
    response = handler(request, *args, **kwargs)
  File "/usr/local/lib/python3.10/site-packages/djoser/views.py", line 171, in me
    return self.retrieve(request, *args, **kwargs)
  File "/usr/local/lib/python3.10/site-packages/rest_framework/mixins.py", line 56, in retrieve
    return Response(serializer.data)
  File "/usr/local/lib/python3.10/site-packages/rest_framework/serializers.py", line 555, in data
    ret = super().data
  File "/usr/local/lib/python3.10/site-packages/rest_framework/serializers.py", line 253, in data
    self._data = self.to_representation(self.instance)
  File "/app/apps/users/serializers.py", line 45, in to_representation
    representation = super(UserSerializer, self).to_representation(instance)
  File "/usr/local/lib/python3.10/site-packages/rest_framework/serializers.py", line 522, in to_representation
    ret[field.field_name] = field.to_representation(attribute)
  File "/usr/local/lib/python3.10/site-packages/rest_framework/fields.py", line 1885, in to_representation
    method = getattr(self.parent, self.method_name)
AttributeError: 'UserSerializer' object has no attribute 'get_full_name'
2022-01-11 11:09:07,244 django.request ERROR    Internal Server Error: /api/v1/auth/users/me/
Traceback (most recent call last):
  File "/usr/local/lib/python3.10/site-packages/django/core/handlers/exception.py", line 47, in inner
    response = get_response(request)
  File "/usr/local/lib/python3.10/site-packages/django/core/handlers/base.py", line 181, in _get_response
    response = wrapped_callback(request, *callback_args, **callback_kwargs)
  File "/usr/local/lib/python3.10/site-packages/django/views/decorators/csrf.py", line 54, in wrapped_view
    return view_func(*args, **kwargs)
  File "/usr/local/lib/python3.10/site-packages/rest_framework/viewsets.py", line 125, in view
    return self.dispatch(request, *args, **kwargs)
  File "/usr/local/lib/python3.10/site-packages/rest_framework/views.py", line 509, in dispatch
    response = self.handle_exception(exc)
  File "/usr/local/lib/python3.10/site-packages/rest_framework/views.py", line 469, in handle_exception
    self.raise_uncaught_exception(exc)
  File "/usr/local/lib/python3.10/site-packages/rest_framework/views.py", line 480, in raise_uncaught_exception
    raise exc
  File "/usr/local/lib/python3.10/site-packages/rest_framework/views.py", line 506, in dispatch
    response = handler(request, *args, **kwargs)
  File "/usr/local/lib/python3.10/site-packages/djoser/views.py", line 171, in me
    return self.retrieve(request, *args, **kwargs)
  File "/usr/local/lib/python3.10/site-packages/rest_framework/mixins.py", line 56, in retrieve
    return Response(serializer.data)
  File "/usr/local/lib/python3.10/site-packages/rest_framework/serializers.py", line 555, in data
    ret = super().data
  File "/usr/local/lib/python3.10/site-packages/rest_framework/serializers.py", line 253, in data
    self._data = self.to_representation(self.instance)
  File "/app/apps/users/serializers.py", line 45, in to_representation
    representation = super(UserSerializer, self).to_representation(instance)
  File "/usr/local/lib/python3.10/site-packages/rest_framework/serializers.py", line 522, in to_representation
    ret[field.field_name] = field.to_representation(attribute)
  File "/usr/local/lib/python3.10/site-packages/rest_framework/fields.py", line 1885, in to_representation
    method = getattr(self.parent, self.method_name)
AttributeError: 'UserSerializer' object has no attribute 'get_full_name'
2022-01-11 11:09:33,788 django.request ERROR    Internal Server Error: /api/v1/auth/users/me/
Traceback (most recent call last):
  File "/usr/local/lib/python3.10/site-packages/django/core/handlers/exception.py", line 47, in inner
    response = get_response(request)
  File "/usr/local/lib/python3.10/site-packages/django/core/handlers/base.py", line 181, in _get_response
    response = wrapped_callback(request, *callback_args, **callback_kwargs)
  File "/usr/local/lib/python3.10/site-packages/django/views/decorators/csrf.py", line 54, in wrapped_view
    return view_func(*args, **kwargs)
  File "/usr/local/lib/python3.10/site-packages/rest_framework/viewsets.py", line 125, in view
    return self.dispatch(request, *args, **kwargs)
  File "/usr/local/lib/python3.10/site-packages/rest_framework/views.py", line 509, in dispatch
    response = self.handle_exception(exc)
  File "/usr/local/lib/python3.10/site-packages/rest_framework/views.py", line 469, in handle_exception
    self.raise_uncaught_exception(exc)
  File "/usr/local/lib/python3.10/site-packages/rest_framework/views.py", line 480, in raise_uncaught_exception
    raise exc
  File "/usr/local/lib/python3.10/site-packages/rest_framework/views.py", line 506, in dispatch
    response = handler(request, *args, **kwargs)
  File "/usr/local/lib/python3.10/site-packages/djoser/views.py", line 171, in me
    return self.retrieve(request, *args, **kwargs)
  File "/usr/local/lib/python3.10/site-packages/rest_framework/mixins.py", line 56, in retrieve
    return Response(serializer.data)
  File "/usr/local/lib/python3.10/site-packages/rest_framework/serializers.py", line 555, in data
    ret = super().data
  File "/usr/local/lib/python3.10/site-packages/rest_framework/serializers.py", line 253, in data
    self._data = self.to_representation(self.instance)
  File "/app/apps/users/serializers.py", line 45, in to_representation
    representation = super(UserSerializer, self).to_representation(instance)
  File "/usr/local/lib/python3.10/site-packages/rest_framework/serializers.py", line 522, in to_representation
    ret[field.field_name] = field.to_representation(attribute)
  File "/usr/local/lib/python3.10/site-packages/rest_framework/fields.py", line 1885, in to_representation
    method = getattr(self.parent, self.method_name)
AttributeError: 'UserSerializer' object has no attribute 'get_full_name'
2022-01-11 11:10:21,132 django.request ERROR    Internal Server Error: /api/v1/auth/users/me/
Traceback (most recent call last):
  File "/usr/local/lib/python3.10/site-packages/django/core/handlers/exception.py", line 47, in inner
    response = get_response(request)
  File "/usr/local/lib/python3.10/site-packages/django/core/handlers/base.py", line 181, in _get_response
    response = wrapped_callback(request, *callback_args, **callback_kwargs)
  File "/usr/local/lib/python3.10/site-packages/django/views/decorators/csrf.py", line 54, in wrapped_view
    return view_func(*args, **kwargs)
  File "/usr/local/lib/python3.10/site-packages/rest_framework/viewsets.py", line 125, in view
    return self.dispatch(request, *args, **kwargs)
  File "/usr/local/lib/python3.10/site-packages/rest_framework/views.py", line 509, in dispatch
    response = self.handle_exception(exc)
  File "/usr/local/lib/python3.10/site-packages/rest_framework/views.py", line 469, in handle_exception
    self.raise_uncaught_exception(exc)
  File "/usr/local/lib/python3.10/site-packages/rest_framework/views.py", line 480, in raise_uncaught_exception
    raise exc
  File "/usr/local/lib/python3.10/site-packages/rest_framework/views.py", line 506, in dispatch
    response = handler(request, *args, **kwargs)
  File "/usr/local/lib/python3.10/site-packages/djoser/views.py", line 171, in me
    return self.retrieve(request, *args, **kwargs)
  File "/usr/local/lib/python3.10/site-packages/rest_framework/mixins.py", line 56, in retrieve
    return Response(serializer.data)
  File "/usr/local/lib/python3.10/site-packages/rest_framework/serializers.py", line 555, in data
    ret = super().data
  File "/usr/local/lib/python3.10/site-packages/rest_framework/serializers.py", line 253, in data
    self._data = self.to_representation(self.instance)
  File "/app/apps/users/serializers.py", line 45, in to_representation
    representation = super(UserSerializer, self).to_representation(instance)
  File "/usr/local/lib/python3.10/site-packages/rest_framework/serializers.py", line 522, in to_representation
    ret[field.field_name] = field.to_representation(attribute)
  File "/usr/local/lib/python3.10/site-packages/rest_framework/fields.py", line 1885, in to_representation
    method = getattr(self.parent, self.method_name)
AttributeError: 'UserSerializer' object has no attribute 'get_full_name'
2022-01-11 11:10:28,692 django.request WARNING  Not Found: /api/v1/
2022-01-11 11:10:49,505 django.request WARNING  Bad Request: /api/v1/auth/jwt/create/
2022-01-11 11:11:07,206 django.request WARNING  Not Found: /api/v1/
2022-01-11 11:11:16,487 django.request WARNING  Not Found: /api/v1/profile/
2022-01-11 11:11:31,323 django.request WARNING  Unauthorized: /api/v1/profile/agents/all/
2022-01-11 11:12:09,255 tornado.general WARNING  404 GET /worker/celery@088b1118b400 (192.168.112.1): Unknown worker 'celery@088b1118b400'
2022-01-11 13:50:18,159 flower.command WARNING  You have incorrectly specified the following celery arguments after flower command: ['--broker']. Please specify them after celery command instead following this template: celery [celery args] flower [flower args].
2022-01-11 13:50:19,040 flower.command INFO     Visit me at http://localhost:5555
2022-01-11 13:50:19,050 flower.command INFO     Broker: redis://redis:6379/0
2022-01-11 13:50:19,054 flower.command INFO     Registered tasks: 
['celery.accumulate',
 'celery.backend_cleanup',
 'celery.chain',
 'celery.chord',
 'celery.chord_unlock',
 'celery.chunks',
 'celery.group',
 'celery.map',
 'celery.starmap',
 'djcelery_email_send_multiple']
2022-01-11 13:50:19,064 kombu.mixins INFO     Connected to redis://redis:6379/0
2022-01-11 13:50:20,123 flower.inspector WARNING  Inspect method active_queues failed
2022-01-11 13:50:20,127 flower.inspector WARNING  Inspect method registered failed
2022-01-11 13:50:20,142 flower.inspector WARNING  Inspect method scheduled failed
2022-01-11 13:50:20,143 flower.inspector WARNING  Inspect method stats failed
2022-01-11 13:50:20,143 flower.inspector WARNING  Inspect method reserved failed
2022-01-11 13:50:20,146 flower.inspector WARNING  Inspect method active failed
2022-01-11 13:50:21,145 flower.inspector WARNING  Inspect method conf failed
2022-01-11 13:50:21,643 flower.inspector WARNING  Inspect method revoked failed
2022-01-11 13:50:22,296 django.utils.autoreload INFO     Watching for file changes with StatReloader
2022-01-11 13:50:53,720 django.utils.autoreload INFO     /app/apps/profiles/urls.py changed, reloading.
2022-01-11 13:50:54,813 django.utils.autoreload INFO     Watching for file changes with StatReloader
